GTCEuStartupEvents.registry('gtceu:recipe_type', event => {
        event.create('extreme_pressure_drilling_rig')
            .category('multiblock')
            .setEUIO('in')
            .setMaxIOSize(1, 2, 2, 2)
            .setProgressBar($GTSACGuiTextures.PROGRESS_BAR_DRILL, FillDirection.UP_TO_DOWN)
            .setSound(GTSoundEntries.ARC)
})



GTCEuStartupEvents.registry('gtceu:machine', event => {
    event.create('extreme_pressure_drilling_rig', 'multiblock')
        .rotationState(RotationState.ALL)
        .recipeType('extreme_pressure_drilling_rig')
        .appearanceBlock(() => Block.getBlock('gtsac:pressure_resistant_casing'))
        .recipeModifiers([GTRecipeModifiers.ELECTRIC_OVERCLOCK.apply(OverclockingLogic.NON_PERFECT_OVERCLOCK_SUBTICK), GTRecipeModifiers.BATCH_MODE])
        .pattern(definition => FactoryBlockPattern.start()
        .aisle("AAAAAAAAAAAAABCBAAAAAAAAAAAAA", "AAAAAAAAAAAAAABAAAAAAAAAAAAAA", "AAAAAAAAAAAAAAAAAAAAAAAAAAAAA", "AAAAAAAAAAAAAAAAAAAAAAAAAAAAA", "AAAAAAAAAAAAAAAAAAAAAAAAAAAAA", "AAAAAAAAAAAAAAAAAAAAAAAAAAAAA", "AAAAAAAAAAAAAAAAAAAAAAAAAAAAA", "AAAAAAAAAAAAAAAAAAAAAAAAAAAAA", "AAAAAAAAAAAAAAAAAAAAAAAAAAAAA", "AAAAAAAAAAAAAAAAAAAAAAAAAAAAA", "AAAAAAAAAAAAAAAAAAAAAAAAAAAAA", "AAAAAAAAAAAAAAAAAAAAAAAAAAAAA", "AAAAAAAAAAAAAAAAAAAAAAAAAAAAA", "AAAAAAAAAAAAAAAAAAAAAAAAAAAAA", "AAAAAAAAAAAAAAAAAAAAAAAAAAAAA", "AAAAAAAAAAAAAAAAAAAAAAAAAAAAA", "AAAAAAAAAAAAAAAAAAAAAAAAAAAAA", "AAAAAAAAAAAAAAAAAAAAAAAAAAAAA", "AAAAAAAAAAAAAAAAAAAAAAAAAAAAA", "AAAAAAAAAAAAAAAAAAAAAAAAAAAAA", "AAAAAAAAAAAAAAAAAAAAAAAAAAAAA", "AAAAAAAAAAAAAAAAAAAAAAAAAAAAA", "AAAAAAAAAAAAAAAAAAAAAAAAAAAAA", "AAAAAAAAAAAAAAAAAAAAAAAAAAAAA", "AAAAAAAAAAAAAAAAAAAAAAAAAAAAA", "AAAAAAAAAAAAAAAAAAAAAAAAAAAAA", "AAAAAAAAAAAAAAAAAAAAAAAAAAAAA", "AAAAAAAAAAAAAAAAAAAAAAAAAAAAA", "AAAAAAAAAAAAAAAAAAAAAAAAAAAAA", "AAAAAAAAAAAAAAAAAAAAAAAAAAAAA", "AAAAAAAAAAAAAAAAAAAAAAAAAAAAA", "AAAAAAAAAAAAAAAAAAAAAAAAAAAAA", "AAAAAAAAAAAAAAAAAAAAAAAAAAAAA")
        .aisle("AAAAAAAAAAAABCCCBAAAAAAAAAAAA", "AAAAAAAAAAAAABCBAAAAAAAAAAAAA", "AAAAAAAAAAAAABCBAAAAAAAAAAAAA", "AAAAAAAAAAAAABCBAAAAAAAAAAAAA", "AAAAAAAAAAAAAABAAAAAAAAAAAAAA", "AAAAAAAAAAAAAAAAAAAAAAAAAAAAA", "AAAAAAAAAAAAAAAAAAAAAAAAAAAAA", "AAAAAAAAAAAAAAAAAAAAAAAAAAAAA", "AAAAAAAAAAAAAAAAAAAAAAAAAAAAA", "AAAAAAAAAAAAAAAAAAAAAAAAAAAAA", "AAAAAAAAAAAAAAAAAAAAAAAAAAAAA", "AAAAAAAAAAAAAAAAAAAAAAAAAAAAA", "AAAAAAAAAAAAAAAAAAAAAAAAAAAAA", "AAAAAAAAAAAAAAAAAAAAAAAAAAAAA", "AAAAAAAAAAAAAAAAAAAAAAAAAAAAA", "AAAAAAAAAAAAAAAAAAAAAAAAAAAAA", "AAAAAAAAAAAAAAAAAAAAAAAAAAAAA", "AAAAAAAAAAAAAAAAAAAAAAAAAAAAA", "AAAAAAAAAAAAAAAAAAAAAAAAAAAAA", "AAAAAAAAAAAAAAAAAAAAAAAAAAAAA", "AAAAAAAAAAAAAAAAAAAAAAAAAAAAA", "AAAAAAAAAAAAAAAAAAAAAAAAAAAAA", "AAAAAAAAAAAAAAAAAAAAAAAAAAAAA", "AAAAAAAAAAAAAAAAAAAAAAAAAAAAA", "AAAAAAAAAAAAAAAAAAAAAAAAAAAAA", "AAAAAAAAAAAAAAAAAAAAAAAAAAAAA", "AAAAAAAAAAAAAAAAAAAAAAAAAAAAA", "AAAAAAAAAAAAAAAAAAAAAAAAAAAAA", "AAAAAAAAAAAAAAAAAAAAAAAAAAAAA", "AAAAAAAAAAAAAAAAAAAAAAAAAAAAA", "AAAAAAAAAAAAAAAAAAAAAAAAAAAAA", "AAAAAAAAAAAAAAAAAAAAAAAAAAAAA", "AAAAAAAAAAAAAAAAAAAAAAAAAAAAA")
        .aisle("AAAAAAAAAAAAABCBAAAAAAAAAAAAA", "AAAAAAAAAAAAAABAAAAAAAAAAAAAA", "AAAAAAAAAAAAAABAAAAAAAAAAAAAA", "AAAAAAAAAAAAABBBAAAAAAAAAAAAA", "AAAAAAAAAAAAABCBAAAAAAAAAAAAA", "AAAAAAAAAAAAABCBAAAAAAAAAAAAA", "AAAAAAAAAAAAABCBAAAAAAAAAAAAA", "AAAAAAAAAAAAAABAAAAAAAAAAAAAA", "AAAAAAAAAAAAAAAAAAAAAAAAAAAAA", "AAAAAAAAAAAAAAAAAAAAAAAAAAAAA", "AAAAAAAAAAAAAAAAAAAAAAAAAAAAA", "AAAAAAAAAAAAAAAAAAAAAAAAAAAAA", "AAAAAAAAAAAAAAAAAAAAAAAAAAAAA", "AAAAAAAAAAAAAAAAAAAAAAAAAAAAA", "AAAAAAAAAAAAAAAAAAAAAAAAAAAAA", "AAAAAAAAAAAAAAAAAAAAAAAAAAAAA", "AAAAAAAAAAAAAAAAAAAAAAAAAAAAA", "AAAAAAAAAAAAAAAAAAAAAAAAAAAAA", "AAAAAAAAAAAAAAAAAAAAAAAAAAAAA", "AAAAAAAAAAAAAAAAAAAAAAAAAAAAA", "AAAAAAAAAAAAAAAAAAAAAAAAAAAAA", "AAAAAAAAAAAAAAAAAAAAAAAAAAAAA", "AAAAAAAAAAAAAAAAAAAAAAAAAAAAA", "AAAAAAAAAAAAAAAAAAAAAAAAAAAAA", "AAAAAAAAAAAAAAAAAAAAAAAAAAAAA", "AAAAAAAAAAAAAAAAAAAAAAAAAAAAA", "AAAAAAAAAAAAAAAAAAAAAAAAAAAAA", "AAAAAAAAAAAAAAAAAAAAAAAAAAAAA", "AAAAAAAAAAAAAAAAAAAAAAAAAAAAA", "AAAAAAAAAAAAAAAAAAAAAAAAAAAAA", "AAAAAAAAAAAAAAAAAAAAAAAAAAAAA", "AAAAAAAAAAAAAAAAAAAAAAAAAAAAA", "AAAAAAAAAAAAAAAAAAAAAAAAAAAAA")
        .aisle("AAAAAAAAAAAAAAAAAAAAAAAAAAAAA", "AAAAAAAAAAAAAAAAAAAAAAAAAAAAA", "AAAAAAAAAAAAAAAAAAAAAAAAAAAAA", "AAAAAAAAAAAAAAAAAAAAAAAAAAAAA", "AAAAAAAAAAAAAABAAAAAAAAAAAAAA", "AAAAAAAAAAAAAABAAAAAAAAAAAAAA", "AAAAAAAAAAAAABBBAAAAAAAAAAAAA", "AAAAAAAAAAAAABCBAAAAAAAAAAAAA", "AAAAAAAAAAAAABCBAAAAAAAAAAAAA", "AAAAAAAAAAAAAABAAAAAAAAAAAAAA", "AAAAAAAAAAAAAAAAAAAAAAAAAAAAA", "AAAAAAAAAAAAAAAAAAAAAAAAAAAAA", "AAAAAAAAAAAAAAAAAAAAAAAAAAAAA", "AAAAAAAAAAAAAAAAAAAAAAAAAAAAA", "AAAAAAAAAAAAAAAAAAAAAAAAAAAAA", "AAAAAAAAAAAAAAAAAAAAAAAAAAAAA", "AAAAAAAAAAAAAAAAAAAAAAAAAAAAA", "AAAAAAAAAAAAAAAAAAAAAAAAAAAAA", "AAAAAAAAAAAAAAAAAAAAAAAAAAAAA", "AAAAAAAAAAAAAAAAAAAAAAAAAAAAA", "AAAAAAAAAAAAAAAAAAAAAAAAAAAAA", "AAAAAAAAAAAAAAAAAAAAAAAAAAAAA", "AAAAAAAAAAAAAAAAAAAAAAAAAAAAA", "AAAAAAAAAAAAAAAAAAAAAAAAAAAAA", "AAAAAAAAAAAAAAAAAAAAAAAAAAAAA", "AAAAAAAAAAAAAAAAAAAAAAAAAAAAA", "AAAAAAAAAAAAAAAAAAAAAAAAAAAAA", "AAAAAAAAAAAAAAAAAAAAAAAAAAAAA", "AAAAAAAAAAAAAAAAAAAAAAAAAAAAA", "AAAAAAAAAAAAAAAAAAAAAAAAAAAAA", "AAAAAAAAAAAAAAAAAAAAAAAAAAAAA", "AAAAAAAAAAAAAAAAAAAAAAAAAAAAA", "AAAAAAAAAAAAAAAAAAAAAAAAAAAAA")
        .aisle("AAAAAAAAAAAAAAAAAAAAAAAAAAAAA", "AAAAAAAAAAAAAAAAAAAAAAAAAAAAA", "AAAAAAAAAAAAAAAAAAAAAAAAAAAAA", "AAAAAAAAAAAAAAAAAAAAAAAAAAAAA", "AAAAAAAAAAAAAAAAAAAAAAAAAAAAA", "AAAAAAAAAAAAAAAAAAAAAAAAAAAAA", "AAAAAAAAAAAAAAAAAAAAAAAAAAAAA", "AAAAAAAAAAAAAABAAAAAAAAAAAAAA", "AAAAAAAAAAAAABBBAAAAAAAAAAAAA", "AAAAAAAAAAAAABCBAAAAAAAAAAAAA", "AAAAAAAAAAAAAABAAAAAAAAAAAAAA", "AAAAAAAAAAAAAAAAAAAAAAAAAAAAA", "AAAAAAAAAAAAAAAAAAAAAAAAAAAAA", "AAAAAAAAAAAAAAAAAAAAAAAAAAAAA", "AAAAAAAAAAAAAAAAAAAAAAAAAAAAA", "AAAAAAAAAAAAAAAAAAAAAAAAAAAAA", "AAAAAAAAAAAAAAAAAAAAAAAAAAAAA", "AAAAAAAAAAAAAAAAAAAAAAAAAAAAA", "AAAAAAAAAAAAAAAAAAAAAAAAAAAAA", "AAAAAAAAAAAAAAAAAAAAAAAAAAAAA", "AAAAAAAAAAAAAAAAAAAAAAAAAAAAA", "AAAAAAAAAAAAAAAAAAAAAAAAAAAAA", "AAAAAAAAAAAAAAAAAAAAAAAAAAAAA", "AAAAAAAAAAAAAAAAAAAAAAAAAAAAA", "AAAAAAAAAAAAAAAAAAAAAAAAAAAAA", "AAAAAAAAAAAAAAAAAAAAAAAAAAAAA", "AAAAAAAAAAAAAAAAAAAAAAAAAAAAA", "AAAAAAAAAAAAAAAAAAAAAAAAAAAAA", "AAAAAAAAAAAAAAAAAAAAAAAAAAAAA", "AAAAAAAAAAAAAAAAAAAAAAAAAAAAA", "AAAAAAAAAAAAAAAAAAAAAAAAAAAAA", "AAAAAAAAAAAAAAAAAAAAAAAAAAAAA", "AAAAAAAAAAAAAAAAAAAAAAAAAAAAA")
        .aisle("AAAAAAAAAAAAAAAAAAAAAAAAAAAAA", "AAAAAAAAAAAAAAAAAAAAAAAAAAAAA", "AAAAAAAAAAAAAAAAAAAAAAAAAAAAA", "AAAAAAAAAAAAAAAAAAAAAAAAAAAAA", "AAAAAAAAAAAAAAAAAAAAAAAAAAAAA", "AAAAAAAAAAAAAAAAAAAAAAAAAAAAA", "AAAAAAAAAAAAAAAAAAAAAAAAAAAAA", "AAAAAAAAAAAAAAAAAAAAAAAAAAAAA", "AAAAAAAAAAAAAABAAAAAAAAAAAAAA", "AAAAAAAAAAAAABCBAAAAAAAAAAAAA", "AAAAAAAAAAAAAABAAAAAAAAAAAAAA", "AAAAAAAAAAAAAAAAAAAAAAAAAAAAA", "AAAAAAAAAAAAAAAAAAAAAAAAAAAAA", "AAAAAAAAAAAAAAAAAAAAAAAAAAAAA", "AAAAAAAAAAAAAAAAAAAAAAAAAAAAA", "AAAAAAAAAAAAAAAAAAAAAAAAAAAAA", "AAAAAAAAAAAAAAAAAAAAAAAAAAAAA", "AAAAAAAAAAAAAAAAAAAAAAAAAAAAA", "AAAAAAAAAAAAAAAAAAAAAAAAAAAAA", "AAAAAAAAAAAAAAAAAAAAAAAAAAAAA", "AAAAAAAAAAAAAAAAAAAAAAAAAAAAA", "AAAAAAAAAAAAAAAAAAAAAAAAAAAAA", "AAAAAAAAAAAAAAAAAAAAAAAAAAAAA", "AAAAAAAAAAAAAAAAAAAAAAAAAAAAA", "AAAAAAAAAAAAAAAAAAAAAAAAAAAAA", "AAAAAAAAAAAAAAAAAAAAAAAAAAAAA", "AAAAAAAAAAAAAAAAAAAAAAAAAAAAA", "AAAAAAAAAAAAAAAAAAAAAAAAAAAAA", "AAAAAAAAAAAAAAAAAAAAAAAAAAAAA", "AAAAAAAAAAAAAAAAAAAAAAAAAAAAA", "AAAAAAAAAAAAAAAAAAAAAAAAAAAAA", "AAAAAAAAAAAAAAAAAAAAAAAAAAAAA", "AAAAAAAAAAAAAAAAAAAAAAAAAAAAA")
        .aisle("AAAAAAAAAAAAAAAAAAAAAAAAAAAAA", "AAAAAAAAAAAAAAAAAAAAAAAAAAAAA", "AAAAAAAAAAAAAAAAAAAAAAAAAAAAA", "AAAAAAAAAAAAAAAAAAAAAAAAAAAAA", "AAAAAAAAAAAAAAAAAAAAAAAAAAAAA", "AAAAAAAAAAAAAAAAAAAAAAAAAAAAA", "AAAAAAAAAAAAAAAAAAAAAAAAAAAAA", "AAAAAAAAAAAAAAAAAAAAAAAAAAAAA", "AAAAAAAAAAAAAAAAAAAAAAAAAAAAA", "AAAAAAAAAAAAABBBAAAAAAAAAAAAA", "AAAAAAAAAAAAABCBAAAAAAAAAAAAA", "AAAAAAAAAAAAABBBAAAAAAAAAAAAA", "AAAAAAAAAAAAABABAAAAAAAAAAAAA", "AAAAAAAAAAAAAAAAAAAAAAAAAAAAA", "AAAAAAAAAAAAAAAAAAAAAAAAAAAAA", "AAAAAAAAAAAAAAAAAAAAAAAAAAAAA", "AAAAAAAAAAAAAAAAAAAAAAAAAAAAA", "AAAAAAAAAAAAAAAAAAAAAAAAAAAAA", "AAAAAAAAAAAAAAAAAAAAAAAAAAAAA", "AAAAAAAAAAAAAAAAAAAAAAAAAAAAA", "AAAAAAAAAAAAAAAAAAAAAAAAAAAAA", "AAAAAAAAAAAAAAAAAAAAAAAAAAAAA", "AAAAAAAAAAAAAAAAAAAAAAAAAAAAA", "AAAAAAAAAAAAAAAAAAAAAAAAAAAAA", "AAAAAAAAAAAAAAAAAAAAAAAAAAAAA", "AAAAAAAAAAAAAAAAAAAAAAAAAAAAA", "AAAAAAAAAAAAAAAAAAAAAAAAAAAAA", "AAAAAAAAAAAAAAAAAAAAAAAAAAAAA", "AAAAAAAAAAAAAAAAAAAAAAAAAAAAA", "AAAAAAAAAAAAAAAAAAAAAAAAAAAAA", "AAAAAAAAAAAAAAAAAAAAAAAAAAAAA", "AAAAAAAAAAAAAAAAAAAAAAAAAAAAA", "AAAAAAAAAAAAAAAAAAAAAAAAAAAAA")
        .aisle("AAAAAAAAAAAAAAAAAAAAAAAAAAAAA", "AAAAAAAAAAAAAAAAAAAAAAAAAAAAA", "AAAAAAAAAAAAAAAAAAAAAAAAAAAAA", "AAAAAAAAAAAAAAAAAAAAAAAAAAAAA", "AAAAAAAAAAAAAAAAAAAAAAAAAAAAA", "AAAAAAAAAAAAAAAAAAAAAAAAAAAAA", "AAAAAAAAAAAAAAAAAAAAAAAAAAAAA", "AAAAAAAAAAAAAAAAAAAAAAAAAAAAA", "AAAAAAAAAAAAAAAAAAAAAAAAAAAAA", "AAAAAAAAAAAAAABAAAAAAAAAAAAAA", "AAAAAAAAAAAAABCBAAAAAAAAAAAAA", "AAAAAAAAAAAAAABAAAAAAAAAAAAAA", "AAAAAAAAAAAAABABAAAAAAAAAAAAA", "AAAAAAAAAAAAABABAAAAAAAAAAAAA", "AAAAAAAAAAAAABABAAAAAAAAAAAAA", "AAAAAAAAAAAAABABAAAAAAAAAAAAA", "AAAAAAAAAAAAAAAAAAAAAAAAAAAAA", "AAAAAAAAAAAAAAAAAAAAAAAAAAAAA", "AAAAAAAAAAAAAAAAAAAAAAAAAAAAA", "AAAAAAAAAAAAAAAAAAAAAAAAAAAAA", "AAAAAAAAAAAAAAAAAAAAAAAAAAAAA", "AAAAAAAAAAAAAAAAAAAAAAAAAAAAA", "AAAAAAAAAAAAAAAAAAAAAAAAAAAAA", "AAAAAAAAAAAAAAAAAAAAAAAAAAAAA", "AAAAAAAAAAAAAAAAAAAAAAAAAAAAA", "AAAAAAAAAAAAAAAAAAAAAAAAAAAAA", "AAAAAAAAAAAAAAAAAAAAAAAAAAAAA", "AAAAAAAAAAAAAAAAAAAAAAAAAAAAA", "AAAAAAAAAAAAAAAAAAAAAAAAAAAAA", "AAAAAAAAAAAAAAAAAAAAAAAAAAAAA", "AAAAAAAAAAAAAAAAAAAAAAAAAAAAA", "AAAAAAAAAAAAAAAAAAAAAAAAAAAAA", "AAAAAAAAAAAAAAAAAAAAAAAAAAAAA")
        .aisle("AAAAAAAAAAAAAAAAAAAAAAAAAAAAA", "AAAAAAAAAAAAAAAAAAAAAAAAAAAAA", "AAAAAAAAAAAAAAAAAAAAAAAAAAAAA", "AAAAAAAAAAAAAAAAAAAAAAAAAAAAA", "AAAAAAAAAAAAAAAAAAAAAAAAAAAAA", "AAAAAAAAAAAAAAAAAAAAAAAAAAAAA", "AAAAAAAAAAAAAAAAAAAAAAAAAAAAA", "AAAAAAAAAAAAAAAAAAAAAAAAAAAAA", "AAAAAAAAAAAAAAAAAAAAAAAAAAAAA", "AAAAAAAAAAAAAABAAAAAAAAAAAAAA", "AAAAAAAAAAAAABCBAAAAAAAAAAAAA", "AAAAAAAAAAAAAABAAAAAAAAAAAAAA", "AAAAAAAAAAAAAAAAAAAAAAAAAAAAA", "AAAAAAAAAAAAAAAAAAAAAAAAAAAAA", "AAAAAAAAAAAAAAAAAAAAAAAAAAAAA", "AAAAAAAAAAAAABABAAAAAAAAAAAAA", "AAAAAAAAAAAAABABAAAAAAAAAAAAA", "AAAAAAAAAAAAAAAAAAAAAAAAAAAAA", "AAAAAAAAAAAAAAAAAAAAAAAAAAAAA", "AAAAAAAAAAAAAAAAAAAAAAAAAAAAA", "AAAAAAAAAAAAAAAAAAAAAAAAAAAAA", "AAAAAAAAAAAAAAAAAAAAAAAAAAAAA", "AAAAAAAAAAAAAAAAAAAAAAAAAAAAA", "AAAAAAAAAAAAAAAAAAAAAAAAAAAAA", "AAAAAAAAAAAAAAAAAAAAAAAAAAAAA", "AAAAAAAAAAAAAAAAAAAAAAAAAAAAA", "AAAAAAAAAAAAAAAAAAAAAAAAAAAAA", "AAAAAAAAAAAAAAAAAAAAAAAAAAAAA", "AAAAAAAAAAAAAAAAAAAAAAAAAAAAA", "AAAAAAAAAAAAAAAAAAAAAAAAAAAAA", "AAAAAAAAAAAAAAAAAAAAAAAAAAAAA", "AAAAAAAAAAAAAAAAAAAAAAAAAAAAA", "AAAAAAAAAAAAAAAAAAAAAAAAAAAAA")
        .aisle("AAAAAAAAAAAAAAAAAAAAAAAAAAAAA", "AAAAAAAAAAAAAAAAAAAAAAAAAAAAA", "AAAAAAAAAAAAAAAAAAAAAAAAAAAAA", "AAAAAAAAAAAAAAAAAAAAAAAAAAAAA", "AAAAAAAAAAAAAAAAAAAAAAAAAAAAA", "AAAAAAAAAAAAAAAAAAAAAAAAAAAAA", "AAAAAAAAAAAAAAAAAAAAAAAAAAAAA", "AAAAAAAAAAAAAAAAAAAAAAAAAAAAA", "AAAAAAAAAAAAAAAAAAAAAAAAAAAAA", "AAAAAAAAAAAAAAAAAAAAAAAAAAAAA", "AAAAAAAAAAAAACCCAAAAAAAAAAAAA", "AAAAAAAAAAAAACCCAAAAAAAAAAAAA", "AAAAAAAAAAAAACECAAAAAAAAAAAAA", "AAAAAAAAAAAAACECAAAAAAAAAAAAA", "AAAAAAAAAAAAACECAAAAAAAAAAAAA", "AAAAAAAAAAAAACECAAAAAAAAAAAAA", "AAAAAAAAAAAAACECAAAAAAAAAAAAA", "AAAAAAAAAAAAACCCAAAAAAAAAAAAA", "AAAAAAAAAAAAACCCAAAAAAAAAAAAA", "AAAAAAAAAAAAAAAAAAAAAAAAAAAAA", "AAAAAAAAAAAAAAAAAAAAAAAAAAAAA", "AAAAAAAAAAAAAAAAAAAAAAAAAAAAA", "AAAAAAAAAAAAAAAAAAAAAAAAAAAAA", "AAAAAAAAAAAAAAAAAAAAAAAAAAAAA", "AAAAAAAAAAAAAAAAAAAAAAAAAAAAA", "AAAAAAAAAAAAAAAAAAAAAAAAAAAAA", "AAAAAAAAAAAAAAAAAAAAAAAAAAAAA", "AAAAAAAAAAAAAAAAAAAAAAAAAAAAA", "AAAAAAAAAAAAAAAAAAAAAAAAAAAAA", "AAAAAAAAAAAAAAAAAAAAAAAAAAAAA", "AAAAAAAAAAAAAAAAAAAAAAAAAAAAA", "AAAAAAAAAAAAAAAAAAAAAAAAAAAAA", "AAAAAAAAAAAAAAAAAAAAAAAAAAAAA")
        .aisle("AAAAAAAAAAAAAAAAAAAAAAAAAAAAA", "AAAAAAAAAAAAAAAAAAAAAAAAAAAAA", "AAAAAAAAAAAAAAAAAAAAAAAAAAAAA", "AAAAAAAAAAAAAAAAAAAAAAAAAAAAA", "AAAAAAAAAAAAAAAAAAAAAAAAAAAAA", "AAAAAAAAAAAAAAAAAAAAAAAAAAAAA", "AAAAAAAAAAAAAAAAAAAAAAAAAAAAA", "AAAAAAAAAAAAAAAAAAAAAAAAAAAAA", "AAAAAAAAAAAAAAAAAAAAAAAAAAAAA", "AAAAAAAAAAAAACCCAAAAAAAAAAAAA", "AAAAAAAAAAACCAAACCAAAAAAAAAAA", "AAAAAAAAAAACFAAAFCAAAAAAAAAAA", "AAAAAAAAAAACFAAAFCAAAAAAAAAAA", "AAAAAAAAAAACFAGAFCAAAAAAAAAAA", "AAAAAAAAAAACFAAAFCAAAAAAAAAAA", "AAAAAAAAAAACFAAAFCAAAAAAAAAAA", "AAAAAAAAAAACFBABFCAAAAAAAAAAA", "AAAAAAAAAAACFAAAFCAAAAAAAAAAA", "AAAAAAAAAAACCAAACCAAAAAAAAAAA", "AAAAAAAAAAAAACCCAAAAAAAAAAAAA", "AAAAAAAAAAAAAAAAAAAAAAAAAAAAA", "AAAAAAAAAAAAAAAAAAAAAAAAAAAAA", "AAAAAAAAAAAAAAAAAAAAAAAAAAAAA", "AAAAAAAAAAAAAAAAAAAAAAAAAAAAA", "AAAAAAAAAAAAAAAAAAAAAAAAAAAAA", "AAAAAAAAAAAAAAAAAAAAAAAAAAAAA", "AAAAAAAAAAAAAAAAAAAAAAAAAAAAA", "AAAAAAAAAAAAAAAAAAAAAAAAAAAAA", "AAAAAAAAAAAAAAAAAAAAAAAAAAAAA", "AAAAAAAAAAAAAAAAAAAAAAAAAAAAA", "AAAAAAAAAAAAAAAAAAAAAAAAAAAAA", "AAAAAAAAAAAAAAAAAAAAAAAAAAAAA", "AAAAAAAAAAAAAAAAAAAAAAAAAAAAA")
        .aisle("AAAAAAAAAAAAAAAAAAAAAAAAAAAAA", "AAAAAAAAAAAAAAAAAAAAAAAAAAAAA", "AAAAAAAAAAAAAAAAAAAAAAAAAAAAA", "AAAAAAAAAAAAAAAAAAAAAAAAAAAAA", "AAAAAAAAAAAAAAAAAAAAAAAAAAAAA", "AAAAAAAAAAAAAAAAAAAAAAAAAAAAA", "AAAAAAAAAAAAAAAAAAAAAAAAAAAAA", "AAAAAAAAAAAAAAAAAAAAAAAAAAAAA", "AAAAAAAAAAAAAAAAAAAAAAAAAAAAA", "AAAAAAAAAAACCCCCCCAAAAAAAAAAA", "AAAAAAAAAACAAAAAAACAAAAAAAAAA", "AAAAAAAAAACAAAAAAACAAAAAAAAAA", "AAAAAAAAAACAAAAAAACAAAAAAAAAA", "AAAAAAAAAACAAAGAAACAAAAAAAAAA", "AAAAAAAAAACAAAAAAACAAAAAAAAAA", "AAAAAAAAAACAAAAAAACAAAAAAAAAA", "AAAAAAAAAACAABABAACAAAAAAAAAA", "AAAAAAAAAACAAAAAAACAAAAAAAAAA", "AAAAAAAAAACAAAAAAACAAAAAAAAAA", "AAAAAAAAAAACCCACCCAAAAAAAAAAA", "AAAAAAAAAAAAAACAAAAAAAAAAAAAA", "AAAAAAAAAAAAAAAAAAAAAAAAAAAAA", "AAAAAAAAAAAAAAAAAAAAAAAAAAAAA", "AAAAAAAAAAAAAAAAAAAAAAAAAAAAA", "AAAAAAAAAAAAAAAAAAAAAAAAAAAAA", "AAAAAAAAAAAAAAAAAAAAAAAAAAAAA", "AAAAAAAAAAAAAAAAAAAAAAAAAAAAA", "AAAAAAAAAAAAACCCAAAAAAAAAAAAA", "AAAAAAAAAAAAACFCAAAAAAAAAAAAA", "AAAAAAAAAAAAACFCAAAAAAAAAAAAA", "AAAAAAAAAAAAACFCAAAAAAAAAAAAA", "AAAAAAAAAAAAACCCAAAAAAAAAAAAA", "AAAAAAAAAAAAAAAAAAAAAAAAAAAAA")
        .aisle("ABAAAAAAAAAAAAAAAAAAAAAAAAABA", "AAAAAAAAAAAAAAAAAAAAAAAAAAAAA", "AAAAAAAAAAAAAAAAAAAAAAAAAAAAA", "AAAAAAAAAAAAAAAAAAAAAAAAAAAAA", "AAAAAAAAAAAAAAAAAAAAAAAAAAAAA", "AAAAAAAAAAAAAAAAAAAAAAAAAAAAA", "AAAAAAAAAAAAAAHAAAAAAAAAAAAAA", "AAAAAAAAAAAAAAHAAAAAAAAAAAAAA", "AAAAAAAAAAAAAAHAAAAAAAAAAAAAA", "AAAAAAAAAAACCCCCCCAAAAAAAAAAA", "AAAAAAAAAACAAAAAAACAAAAAAAAAA", "AAAAAAAAAAFAAAAAAAFAAAAAAAAAA", "AAAAAAAAAAFAAAAAAAFAAAAAAAAAA", "AAAAAAAAAAFAAAGAAAFAAAAAAAAAA", "AAAAAAAAAAFAAAAAAAFAAAAAAAAAA", "AAAAAAAAAAFAAAAAAAFAAAAAAAAAA", "AAAAAAAAAAFAABABAAFAAAAAAAAAA", "AAAAAAAAAAFAAAAAAAFAAAAAAAAAA", "AAAAAAAAAACAAAAAAACAAAAAAAAAA", "AAAAAAAAAAACAAAAACAAAAAAAAAAA", "AAAAAAAAAAAACCCCCAAAAAAAAAAAA", "AAAAAAAAAAAAAAAAAAAAAAAAAAAAA", "AAAAAAAAAAAAAAAAAAAAAAAAAAAAA", "AAAAAAAAAAAAAAAAAAAAAAAAAAAAA", "AAAAAAAAAAAAAAAAAAAAAAAAAAAAA", "AAAAAAAAAAAAAAAAAAAAAAAAAAAAA", "AAAAAAAAAAAAACCCAAAAAAAAAAAAA", "AAAAAAAAAAAACCACCAAAAAAAAAAAA", "AAAAAAAAAAAACAAACAAAAAAAAAAAA", "AAAAAAAAAAAACAAACAAAAAAAAAAAA", "AAAAAAAAAAAACAAACAAAAAAAAAAAA", "AAAAAAAAAAAACCACCAAAAAAAAAAAA", "AAAAAAAAAAAAACCCAAAAAAAAAAAAA")
        .aisle("BCBAAAAAAAAAAAAAAAAAAAAAAABCB", "ABAAAAAAAAAAAAAAAAAAAAAAAAABA", "ABAAAAAAAAAAAAAAAAAAAAAAAAABA", "ABBAAAAAAAAAAAHAAAAAAAAAAABBA", "AABAAAAAAAAAAAHAAAAAAAAAAABAA", "AABAAAAAAAAAAAHAAAAAAAAAAABAA", "AABBAAAAAAAAAHIHAAAAAAAAABBAA", "AAABAAAAAAAAAHIHAAAAAAAAABAAA", "AAABBAAAAAAAAHIHAAAAAAAABBAAA", "AAAABBBAAACCCCCCCCCAAABBBAAAA", "AAAAAABBBCAAAHFHAAACBBBAAAAAA", "AAAAAABAACAAAJJJAAACAABAAAAAA", "AAAAAABBACAAAJJJAAACABBAAAAAA", "AAAAAAABACAAAJGJAAACABAAAAAAA", "AAAAAAABACAAAJJJAAACABAAAAAAA", "AAAAAAABBCAAAJJJAAACBBAAAAAAA", "AAAAAAAABCBBBHFHBBBCBAAAAAAAA", "AAAAAAAAACAAAHJHAAACAAAAAAAAA", "AAAAAAAAACAAAHJHAAACAAAAAAAAA", "AAAAAAAAAACCAHJHACCAAAAAAAAAA", "AAAAAAAAAAAACHHHCAAAAAAAAAAAA", "AAAAAAAAAAAAAHJHAAAAAAAAAAAAA", "AAAAAAAAAAAAAHJHAAAAAAAAAAAAA", "AAAAAAAAAAAAAHJHAAAAAAAAAAAAA", "AAAAAAAAAAAAAHJHAAAAAAAAAAAAA", "AAAAAAAAAAAAAHHHAAAAAAAAAAAAA", "AAAAAAAAAAAACCCCCAAAAAAAAAAAA", "AAAAAAAAAAACCAAACCAAAAAAAAAAA", "AAAAAAAAAAACAAAAACAAAAAAAAAAA", "AAAAAAAAAAACAAAAACAAAAAAAAAAA", "AAAAAAAAAAACAAAAACAAAAAAAAAAA", "AAAAAAAAAAACCAAACCAAAAAAAAAAA", "AAAAAAAAAAAACCECCAAAAAAAAAAAA")
        .aisle("CCCAAAAAAAAAAAHAAAAAAAAAAACCC", "BCBAAAAAAAAAAAHAAAAAAAAAAABCB", "ACBAAAAAAAAAAAHAAAAAAAAAAABCA", "ACBAAAAAAAAAAHGHAAAAAAAAAABCA", "ABCBAAAAAAAAAHGHAAAAAAAAABCBA", "AACBAAAAAAAAAHGHAAAAAAAAABCAA", "AACBAAAAAAAAHIGIHAAAAAAAABCAA", "AABCBAAAAAAAHIGIHAAAAAAABCBAA", "AAACBBAAAAAAHIGIHAAAAAABBCAAA", "AAABCCBBBBCCCCGCCCCABBBCCBAAA", "AAAABBCCCCAAAFGFAAACCCCBBAAAA", "AAAAAABBBCAAAJGJAAACBBBAAAAAA", "AAAAAAAAAEAAAJGJAAAEAAAAAAAAA", "AAAAAAAAAEGGGGGGGGGEAAAAAAAAA", "AAAAAAAAAEAAAJGJAAAEAAAAAAAAA", "AAAAAAAAAEAAAJGJAAAEAAAAAAAAA", "AAAAAAAAAEAAAFGFAAAEAAAAAAAAA", "AAAAAAAAACAAAJGJAAACAAAAAAAAA", "AAAAAAAAACAAAJGJAAACAAAAAAAAA", "AAAAAAAAAACAAJGJAACAAAAAAAAAA", "AAAAAAAAAAACCHGHCCAAAAAAAAAAA", "AAAAAAAAAAAAAJGJAAAAAAAAAAAAA", "AAAAAAAAAAAAAJGJAAAAAAAAAAAAA", "AAAAAAAAAAAAAJGJAAAAAAAAAAAAA", "AAAAAAAAAAAAAJGJAAAAAAAAAAAAA", "AAAAAAAAAAAAAHGHAAAAAAAAAAAAA", "AAAAAAAAAAAACCGCCAAAAAAAAAAAA", "AAAAAAAAAAACAAAAACAAAAAAAAAAA", "AAAAAAAAAAAFAAAAAFAAAAAAAAAAA", "AAAAAAAAAAAFAAAAAFAAAAAAAAAAA", "AAAAAAAAAAAFAAAAAFAAAAAAAAAAA", "AAAAAAAAAAACAAAAACAAAAAAAAAAA", "AAAAAAAAAAAACEEECAAAAAAAAAAAA")
        .aisle("BCBAAAAAAAAAAAAAAAAAAAAAAABCB", "ABAAAAAAAAAAAAAAAAAAAAAAAAABA", "ABAAAAAAAAAAAAAAAAAAAAAAAAABA", "ABBAAAAAAAAAAAHAAAAAAAAAAABBA", "AABAAAAAAAAAAAHAAAAAAAAAAABAA", "AABAAAAAAAAAAAHAAAAAAAAAAABAA", "AABBAAAAAAAAAHIHAAAAAAAAABBAA", "AAABAAAAAAAAAHIHAAAAAAAAABAAA", "AAABBAAAAAAAAHIHAAAAAAAABBAAA", "AAAABBBAAACCCCCCCCCAAABBBAAAA", "AAAAAABBBCAAAHFHAAACBBBAAAAAA", "AAAAAABAACAAAJ@JAAACAABAAAAAA", "AAAAAABBACAAAJJJAAACABBAAAAAA", "AAAAAAABACAAAJJJAAACABAAAAAAA", "AAAAAAABACAAAJJJAAACABAAAAAAA", "AAAAAAABBCAAAJJJAAACBBAAAAAAA", "AAAAAAAABCBBBHFHBBBCBAAAAAAAA", "AAAAAAAAACAAAHJHAAACAAAAAAAAA", "AAAAAAAAACAAAHJHAAACAAAAAAAAA", "AAAAAAAAAACCAHJHACCAAAAAAAAAA", "AAAAAAAAAAAACHHHCAAAAAAAAAAAA", "AAAAAAAAAAAAAHJHAAAAAAAAAAAAA", "AAAAAAAAAAAAAHJHAAAAAAAAAAAAA", "AAAAAAAAAAAAAHJHAAAAAAAAAAAAA", "AAAAAAAAAAAAAHJHAAAAAAAAAAAAA", "AAAAAAAAAAAAAHHHAAAAAAAAAAAAA", "AAAAAAAAAAAACCCCCAAAAAAAAAAAA", "AAAAAAAAAAACCAAACCAAAAAAAAAAA", "AAAAAAAAAAACAAAAACAAAAAAAAAAA", "AAAAAAAAAAACAAAAACAAAAAAAAAAA", "AAAAAAAAAAACAAAAACAAAAAAAAAAA", "AAAAAAAAAAACCAAACCAAAAAAAAAAA", "AAAAAAAAAAAACCECCAAAAAAAAAAAA")
        .aisle("ABAAAAAAAAAAAAAAAAAAAAAAAAABA", "AAAAAAAAAAAAAAAAAAAAAAAAAAAAA", "AAAAAAAAAAAAAAAAAAAAAAAAAAAAA", "AAAAAAAAAAAAAAAAAAAAAAAAAAAAA", "AAAAAAAAAAAAAAAAAAAAAAAAAAAAA", "AAAAAAAAAAAAAAAAAAAAAAAAAAAAA", "AAAAAAAAAAAAAAHAAAAAAAAAAAAAA", "AAAAAAAAAAAAAAHAAAAAAAAAAAAAA", "AAAAAAAAAAAAAAHAAAAAAAAAAAAAA", "AAAAAAAAAAACCCCCCCAAAAAAAAAAA", "AAAAAAAAAACAAAAAAACAAAAAAAAAA", "AAAAAAAAAAFAAAAAAAFAAAAAAAAAA", "AAAAAAAAAAFAAAAAAAFAAAAAAAAAA", "AAAAAAAAAAFAAAAAAAFAAAAAAAAAA", "AAAAAAAAAAFAAAAAAAFAAAAAAAAAA", "AAAAAAAAAAFAAAAAAAFAAAAAAAAAA", "AAAAAAAAAAFAABABAAFAAAAAAAAAA", "AAAAAAAAAAFAAAAAAAFAAAAAAAAAA", "AAAAAAAAAACAAAAAAACAAAAAAAAAA", "AAAAAAAAAAACCAAAACAAAAAAAAAAA", "AAAAAAAAAAAACCCCCAAAAAAAAAAAA", "AAAAAAAAAAAAAAAAAAAAAAAAAAAAA", "AAAAAAAAAAAAAAAAAAAAAAAAAAAAA", "AAAAAAAAAAAAAAAAAAAAAAAAAAAAA", "AAAAAAAAAAAAAAAAAAAAAAAAAAAAA", "AAAAAAAAAAAAAAAAAAAAAAAAAAAAA", "AAAAAAAAAAAAACCCAAAAAAAAAAAAA", "AAAAAAAAAAAACCACCAAAAAAAAAAAA", "AAAAAAAAAAAACAAACAAAAAAAAAAAA", "AAAAAAAAAAAACAAACAAAAAAAAAAAA", "AAAAAAAAAAAACAAACAAAAAAAAAAAA", "AAAAAAAAAAAACCACCAAAAAAAAAAAA", "AAAAAAAAAAAAACCCAAAAAAAAAAAAA")
        .aisle("AAAAAAAAAAAAAAAAAAAAAAAAAAAAA", "AAAAAAAAAAAAAAAAAAAAAAAAAAAAA", "AAAAAAAAAAAAAAAAAAAAAAAAAAAAA", "AAAAAAAAAAAAAAAAAAAAAAAAAAAAA", "AAAAAAAAAAAAAAAAAAAAAAAAAAAAA", "AAAAAAAAAAAAAAAAAAAAAAAAAAAAA", "AAAAAAAAAAAAAAAAAAAAAAAAAAAAA", "AAAAAAAAAAAAAAAAAAAAAAAAAAAAA", "AAAAAAAAAAAAAAAAAAAAAAAAAAAAA", "AAAAAAAAAAACCCCCCCAAAAAAAAAAA", "AAAAAAAAAACAAAAAAACAAAAAAAAAA", "AAAAAAAAAACAAAAAAACAAAAAAAAAA", "AAAAAAAAAACAAAAAAACAAAAAAAAAA", "AAAAAAAAAACAAAAAAACAAAAAAAAAA", "AAAAAAAAAACAAAAAAACAAAAAAAAAA", "AAAAAAAAAACAAAAAAACAAAAAAAAAA", "AAAAAAAAAACAABABAACAAAAAAAAAA", "AAAAAAAAAACAAAAAAACAAAAAAAAAA", "AAAAAAAAAACAAAAAAACAAAAAAAAAA", "AAAAAAAAAAACCCACCCAAAAAAAAAAA", "AAAAAAAAAAAAAACAAAAAAAAAAAAAA", "AAAAAAAAAAAAAAAAAAAAAAAAAAAAA", "AAAAAAAAAAAAAAAAAAAAAAAAAAAAA", "AAAAAAAAAAAAAAAAAAAAAAAAAAAAA", "AAAAAAAAAAAAAAAAAAAAAAAAAAAAA", "AAAAAAAAAAAAAAAAAAAAAAAAAAAAA", "AAAAAAAAAAAAAAAAAAAAAAAAAAAAA", "AAAAAAAAAAAAACCCAAAAAAAAAAAAA", "AAAAAAAAAAAAACFCAAAAAAAAAAAAA", "AAAAAAAAAAAAACFCAAAAAAAAAAAAA", "AAAAAAAAAAAAACFCAAAAAAAAAAAAA", "AAAAAAAAAAAAACCCAAAAAAAAAAAAA", "AAAAAAAAAAAAAAAAAAAAAAAAAAAAA")
        .aisle("AAAAAAAAAAAAAAAAAAAAAAAAAAAAA", "AAAAAAAAAAAAAAAAAAAAAAAAAAAAA", "AAAAAAAAAAAAAAAAAAAAAAAAAAAAA", "AAAAAAAAAAAAAAAAAAAAAAAAAAAAA", "AAAAAAAAAAAAAAAAAAAAAAAAAAAAA", "AAAAAAAAAAAAAAAAAAAAAAAAAAAAA", "AAAAAAAAAAAAAAAAAAAAAAAAAAAAA", "AAAAAAAAAAAAAAAAAAAAAAAAAAAAA", "AAAAAAAAAAAAAAAAAAAAAAAAAAAAA", "AAAAAAAAAAAAACCCAAAAAAAAAAAAA", "AAAAAAAAAAACCAAACCAAAAAAAAAAA", "AAAAAAAAAAACFAAAFCAAAAAAAAAAA", "AAAAAAAAAAACFAAAFCAAAAAAAAAAA", "AAAAAAAAAAACFAAAFCAAAAAAAAAAA", "AAAAAAAAAAACFAAAFCAAAAAAAAAAA", "AAAAAAAAAAACFAAAFCAAAAAAAAAAA", "AAAAAAAAAAACFBABFCAAAAAAAAAAA", "AAAAAAAAAAACFAAAFCAAAAAAAAAAA", "AAAAAAAAAAACCAAACCAAAAAAAAAAA", "AAAAAAAAAAAAACCCAAAAAAAAAAAAA", "AAAAAAAAAAAAAAAAAAAAAAAAAAAAA", "AAAAAAAAAAAAAAAAAAAAAAAAAAAAA", "AAAAAAAAAAAAAAAAAAAAAAAAAAAAA", "AAAAAAAAAAAAAAAAAAAAAAAAAAAAA", "AAAAAAAAAAAAAAAAAAAAAAAAAAAAA", "AAAAAAAAAAAAAAAAAAAAAAAAAAAAA", "AAAAAAAAAAAAAAAAAAAAAAAAAAAAA", "AAAAAAAAAAAAAAAAAAAAAAAAAAAAA", "AAAAAAAAAAAAAAAAAAAAAAAAAAAAA", "AAAAAAAAAAAAAAAAAAAAAAAAAAAAA", "AAAAAAAAAAAAAAAAAAAAAAAAAAAAA", "AAAAAAAAAAAAAAAAAAAAAAAAAAAAA", "AAAAAAAAAAAAAAAAAAAAAAAAAAAAA")
        .aisle("AAAAAAAAAAAAAAAAAAAAAAAAAAAAA", "AAAAAAAAAAAAAAAAAAAAAAAAAAAAA", "AAAAAAAAAAAAAAAAAAAAAAAAAAAAA", "AAAAAAAAAAAAAAAAAAAAAAAAAAAAA", "AAAAAAAAAAAAAAAAAAAAAAAAAAAAA", "AAAAAAAAAAAAAAAAAAAAAAAAAAAAA", "AAAAAAAAAAAAAAAAAAAAAAAAAAAAA", "AAAAAAAAAAAAAAAAAAAAAAAAAAAAA", "AAAAAAAAAAAAAAAAAAAAAAAAAAAAA", "AAAAAAAAAAAAAAAAAAAAAAAAAAAAA", "AAAAAAAAAAAAACCCAAAAAAAAAAAAA", "AAAAAAAAAAAAACCCAAAAAAAAAAAAA", "AAAAAAAAAAAAACACAAAAAAAAAAAAA", "AAAAAAAAAAAAACACAAAAAAAAAAAAA", "AAAAAAAAAAAAACCCAAAAAAAAAAAAA", "AAAAAAAAAAAAACECAAAAAAAAAAAAA", "AAAAAAAAAAAAACECAAAAAAAAAAAAA", "AAAAAAAAAAAAACCCAAAAAAAAAAAAA", "AAAAAAAAAAAAACCCAAAAAAAAAAAAA", "AAAAAAAAAAAAAAAAAAAAAAAAAAAAA", "AAAAAAAAAAAAAAAAAAAAAAAAAAAAA", "AAAAAAAAAAAAAAAAAAAAAAAAAAAAA", "AAAAAAAAAAAAAAAAAAAAAAAAAAAAA", "AAAAAAAAAAAAAAAAAAAAAAAAAAAAA", "AAAAAAAAAAAAAAAAAAAAAAAAAAAAA", "AAAAAAAAAAAAAAAAAAAAAAAAAAAAA", "AAAAAAAAAAAAAAAAAAAAAAAAAAAAA", "AAAAAAAAAAAAAAAAAAAAAAAAAAAAA", "AAAAAAAAAAAAAAAAAAAAAAAAAAAAA", "AAAAAAAAAAAAAAAAAAAAAAAAAAAAA", "AAAAAAAAAAAAAAAAAAAAAAAAAAAAA", "AAAAAAAAAAAAAAAAAAAAAAAAAAAAA", "AAAAAAAAAAAAAAAAAAAAAAAAAAAAA")
        .aisle("AAAAAAAAAAAAAAAAAAAAAAAAAAAAA", "AAAAAAAAAAAAAAAAAAAAAAAAAAAAA", "AAAAAAAAAAAAAAAAAAAAAAAAAAAAA", "AAAAAAAAAAAAAAAAAAAAAAAAAAAAA", "AAAAAAAAAAAAAAAAAAAAAAAAAAAAA", "AAAAAAAAAAAAAAAAAAAAAAAAAAAAA", "AAAAAAAAAAAAAAAAAAAAAAAAAAAAA", "AAAAAAAAAAAAAAAAAAAAAAAAAAAAA", "AAAAAAAAAAAAAAAAAAAAAAAAAAAAA", "AAAAAAAAAAAAAABAAAAAAAAAAAAAA", "AAAAAAAAAAAAABCBAAAAAAAAAAAAA", "AAAAAAAAAAAAAABAAAAAAAAAAAAAA", "AAAAAAAAAAAAAAAAAAAAAAAAAAAAA", "AAAAAAAAAAAAAAAAAAAAAAAAAAAAA", "AAAAAAAAAAAAAAAAAAAAAAAAAAAAA", "AAAAAAAAAAAAABABAAAAAAAAAAAAA", "AAAAAAAAAAAAABABAAAAAAAAAAAAA", "AAAAAAAAAAAAAAAAAAAAAAAAAAAAA", "AAAAAAAAAAAAAAAAAAAAAAAAAAAAA", "AAAAAAAAAAAAAAAAAAAAAAAAAAAAA", "AAAAAAAAAAAAAAAAAAAAAAAAAAAAA", "AAAAAAAAAAAAAAAAAAAAAAAAAAAAA", "AAAAAAAAAAAAAAAAAAAAAAAAAAAAA", "AAAAAAAAAAAAAAAAAAAAAAAAAAAAA", "AAAAAAAAAAAAAAAAAAAAAAAAAAAAA", "AAAAAAAAAAAAAAAAAAAAAAAAAAAAA", "AAAAAAAAAAAAAAAAAAAAAAAAAAAAA", "AAAAAAAAAAAAAAAAAAAAAAAAAAAAA", "AAAAAAAAAAAAAAAAAAAAAAAAAAAAA", "AAAAAAAAAAAAAAAAAAAAAAAAAAAAA", "AAAAAAAAAAAAAAAAAAAAAAAAAAAAA", "AAAAAAAAAAAAAAAAAAAAAAAAAAAAA", "AAAAAAAAAAAAAAAAAAAAAAAAAAAAA")
        .aisle("AAAAAAAAAAAAAAAAAAAAAAAAAAAAA", "AAAAAAAAAAAAAAAAAAAAAAAAAAAAA", "AAAAAAAAAAAAAAAAAAAAAAAAAAAAA", "AAAAAAAAAAAAAAAAAAAAAAAAAAAAA", "AAAAAAAAAAAAAAAAAAAAAAAAAAAAA", "AAAAAAAAAAAAAAAAAAAAAAAAAAAAA", "AAAAAAAAAAAAAAAAAAAAAAAAAAAAA", "AAAAAAAAAAAAAAAAAAAAAAAAAAAAA", "AAAAAAAAAAAAAAAAAAAAAAAAAAAAA", "AAAAAAAAAAAAAABAAAAAAAAAAAAAA", "AAAAAAAAAAAAABCBAAAAAAAAAAAAA", "AAAAAAAAAAAAAABAAAAAAAAAAAAAA", "AAAAAAAAAAAAABABAAAAAAAAAAAAA", "AAAAAAAAAAAAABABAAAAAAAAAAAAA", "AAAAAAAAAAAAABABAAAAAAAAAAAAA", "AAAAAAAAAAAAABABAAAAAAAAAAAAA", "AAAAAAAAAAAAAAAAAAAAAAAAAAAAA", "AAAAAAAAAAAAAAAAAAAAAAAAAAAAA", "AAAAAAAAAAAAAAAAAAAAAAAAAAAAA", "AAAAAAAAAAAAAAAAAAAAAAAAAAAAA", "AAAAAAAAAAAAAAAAAAAAAAAAAAAAA", "AAAAAAAAAAAAAAAAAAAAAAAAAAAAA", "AAAAAAAAAAAAAAAAAAAAAAAAAAAAA", "AAAAAAAAAAAAAAAAAAAAAAAAAAAAA", "AAAAAAAAAAAAAAAAAAAAAAAAAAAAA", "AAAAAAAAAAAAAAAAAAAAAAAAAAAAA", "AAAAAAAAAAAAAAAAAAAAAAAAAAAAA", "AAAAAAAAAAAAAAAAAAAAAAAAAAAAA", "AAAAAAAAAAAAAAAAAAAAAAAAAAAAA", "AAAAAAAAAAAAAAAAAAAAAAAAAAAAA", "AAAAAAAAAAAAAAAAAAAAAAAAAAAAA", "AAAAAAAAAAAAAAAAAAAAAAAAAAAAA", "AAAAAAAAAAAAAAAAAAAAAAAAAAAAA")
        .aisle("AAAAAAAAAAAAAAAAAAAAAAAAAAAAA", "AAAAAAAAAAAAAAAAAAAAAAAAAAAAA", "AAAAAAAAAAAAAAAAAAAAAAAAAAAAA", "AAAAAAAAAAAAAAAAAAAAAAAAAAAAA", "AAAAAAAAAAAAAAAAAAAAAAAAAAAAA", "AAAAAAAAAAAAAAAAAAAAAAAAAAAAA", "AAAAAAAAAAAAAAAAAAAAAAAAAAAAA", "AAAAAAAAAAAAAAAAAAAAAAAAAAAAA", "AAAAAAAAAAAAAAAAAAAAAAAAAAAAA", "AAAAAAAAAAAAABBBAAAAAAAAAAAAA", "AAAAAAAAAAAAABCBAAAAAAAAAAAAA", "AAAAAAAAAAAAABBBAAAAAAAAAAAAA", "AAAAAAAAAAAAABABAAAAAAAAAAAAA", "AAAAAAAAAAAAAAAAAAAAAAAAAAAAA", "AAAAAAAAAAAAAAAAAAAAAAAAAAAAA", "AAAAAAAAAAAAAAAAAAAAAAAAAAAAA", "AAAAAAAAAAAAAAAAAAAAAAAAAAAAA", "AAAAAAAAAAAAAAAAAAAAAAAAAAAAA", "AAAAAAAAAAAAAAAAAAAAAAAAAAAAA", "AAAAAAAAAAAAAAAAAAAAAAAAAAAAA", "AAAAAAAAAAAAAAAAAAAAAAAAAAAAA", "AAAAAAAAAAAAAAAAAAAAAAAAAAAAA", "AAAAAAAAAAAAAAAAAAAAAAAAAAAAA", "AAAAAAAAAAAAAAAAAAAAAAAAAAAAA", "AAAAAAAAAAAAAAAAAAAAAAAAAAAAA", "AAAAAAAAAAAAAAAAAAAAAAAAAAAAA", "AAAAAAAAAAAAAAAAAAAAAAAAAAAAA", "AAAAAAAAAAAAAAAAAAAAAAAAAAAAA", "AAAAAAAAAAAAAAAAAAAAAAAAAAAAA", "AAAAAAAAAAAAAAAAAAAAAAAAAAAAA", "AAAAAAAAAAAAAAAAAAAAAAAAAAAAA", "AAAAAAAAAAAAAAAAAAAAAAAAAAAAA", "AAAAAAAAAAAAAAAAAAAAAAAAAAAAA")
        .aisle("AAAAAAAAAAAAAAAAAAAAAAAAAAAAA", "AAAAAAAAAAAAAAAAAAAAAAAAAAAAA", "AAAAAAAAAAAAAAAAAAAAAAAAAAAAA", "AAAAAAAAAAAAAAAAAAAAAAAAAAAAA", "AAAAAAAAAAAAAAAAAAAAAAAAAAAAA", "AAAAAAAAAAAAAAAAAAAAAAAAAAAAA", "AAAAAAAAAAAAAAAAAAAAAAAAAAAAA", "AAAAAAAAAAAAAAAAAAAAAAAAAAAAA", "AAAAAAAAAAAAAABAAAAAAAAAAAAAA", "AAAAAAAAAAAAABCBAAAAAAAAAAAAA", "AAAAAAAAAAAAAABAAAAAAAAAAAAAA", "AAAAAAAAAAAAAAAAAAAAAAAAAAAAA", "AAAAAAAAAAAAAAAAAAAAAAAAAAAAA", "AAAAAAAAAAAAAAAAAAAAAAAAAAAAA", "AAAAAAAAAAAAAAAAAAAAAAAAAAAAA", "AAAAAAAAAAAAAAAAAAAAAAAAAAAAA", "AAAAAAAAAAAAAAAAAAAAAAAAAAAAA", "AAAAAAAAAAAAAAAAAAAAAAAAAAAAA", "AAAAAAAAAAAAAAAAAAAAAAAAAAAAA", "AAAAAAAAAAAAAAAAAAAAAAAAAAAAA", "AAAAAAAAAAAAAAAAAAAAAAAAAAAAA", "AAAAAAAAAAAAAAAAAAAAAAAAAAAAA", "AAAAAAAAAAAAAAAAAAAAAAAAAAAAA", "AAAAAAAAAAAAAAAAAAAAAAAAAAAAA", "AAAAAAAAAAAAAAAAAAAAAAAAAAAAA", "AAAAAAAAAAAAAAAAAAAAAAAAAAAAA", "AAAAAAAAAAAAAAAAAAAAAAAAAAAAA", "AAAAAAAAAAAAAAAAAAAAAAAAAAAAA", "AAAAAAAAAAAAAAAAAAAAAAAAAAAAA", "AAAAAAAAAAAAAAAAAAAAAAAAAAAAA", "AAAAAAAAAAAAAAAAAAAAAAAAAAAAA", "AAAAAAAAAAAAAAAAAAAAAAAAAAAAA", "AAAAAAAAAAAAAAAAAAAAAAAAAAAAA")
        .aisle("AAAAAAAAAAAAAAAAAAAAAAAAAAAAA", "AAAAAAAAAAAAAAAAAAAAAAAAAAAAA", "AAAAAAAAAAAAAAAAAAAAAAAAAAAAA", "AAAAAAAAAAAAAAAAAAAAAAAAAAAAA", "AAAAAAAAAAAAAAAAAAAAAAAAAAAAA", "AAAAAAAAAAAAAAAAAAAAAAAAAAAAA", "AAAAAAAAAAAAAAAAAAAAAAAAAAAAA", "AAAAAAAAAAAAAABAAAAAAAAAAAAAA", "AAAAAAAAAAAAABBBAAAAAAAAAAAAA", "AAAAAAAAAAAAABCBAAAAAAAAAAAAA", "AAAAAAAAAAAAAABAAAAAAAAAAAAAA", "AAAAAAAAAAAAAAAAAAAAAAAAAAAAA", "AAAAAAAAAAAAAAAAAAAAAAAAAAAAA", "AAAAAAAAAAAAAAAAAAAAAAAAAAAAA", "AAAAAAAAAAAAAAAAAAAAAAAAAAAAA", "AAAAAAAAAAAAAAAAAAAAAAAAAAAAA", "AAAAAAAAAAAAAAAAAAAAAAAAAAAAA", "AAAAAAAAAAAAAAAAAAAAAAAAAAAAA", "AAAAAAAAAAAAAAAAAAAAAAAAAAAAA", "AAAAAAAAAAAAAAAAAAAAAAAAAAAAA", "AAAAAAAAAAAAAAAAAAAAAAAAAAAAA", "AAAAAAAAAAAAAAAAAAAAAAAAAAAAA", "AAAAAAAAAAAAAAAAAAAAAAAAAAAAA", "AAAAAAAAAAAAAAAAAAAAAAAAAAAAA", "AAAAAAAAAAAAAAAAAAAAAAAAAAAAA", "AAAAAAAAAAAAAAAAAAAAAAAAAAAAA", "AAAAAAAAAAAAAAAAAAAAAAAAAAAAA", "AAAAAAAAAAAAAAAAAAAAAAAAAAAAA", "AAAAAAAAAAAAAAAAAAAAAAAAAAAAA", "AAAAAAAAAAAAAAAAAAAAAAAAAAAAA", "AAAAAAAAAAAAAAAAAAAAAAAAAAAAA", "AAAAAAAAAAAAAAAAAAAAAAAAAAAAA", "AAAAAAAAAAAAAAAAAAAAAAAAAAAAA")
        .aisle("AAAAAAAAAAAAAAAAAAAAAAAAAAAAA", "AAAAAAAAAAAAAAAAAAAAAAAAAAAAA", "AAAAAAAAAAAAAAAAAAAAAAAAAAAAA", "AAAAAAAAAAAAAAAAAAAAAAAAAAAAA", "AAAAAAAAAAAAAABAAAAAAAAAAAAAA", "AAAAAAAAAAAAAABAAAAAAAAAAAAAA", "AAAAAAAAAAAAABBBAAAAAAAAAAAAA", "AAAAAAAAAAAAABCBAAAAAAAAAAAAA", "AAAAAAAAAAAAABCBAAAAAAAAAAAAA", "AAAAAAAAAAAAAABAAAAAAAAAAAAAA", "AAAAAAAAAAAAAAAAAAAAAAAAAAAAA", "AAAAAAAAAAAAAAAAAAAAAAAAAAAAA", "AAAAAAAAAAAAAAAAAAAAAAAAAAAAA", "AAAAAAAAAAAAAAAAAAAAAAAAAAAAA", "AAAAAAAAAAAAAAAAAAAAAAAAAAAAA", "AAAAAAAAAAAAAAAAAAAAAAAAAAAAA", "AAAAAAAAAAAAAAAAAAAAAAAAAAAAA", "AAAAAAAAAAAAAAAAAAAAAAAAAAAAA", "AAAAAAAAAAAAAAAAAAAAAAAAAAAAA", "AAAAAAAAAAAAAAAAAAAAAAAAAAAAA", "AAAAAAAAAAAAAAAAAAAAAAAAAAAAA", "AAAAAAAAAAAAAAAAAAAAAAAAAAAAA", "AAAAAAAAAAAAAAAAAAAAAAAAAAAAA", "AAAAAAAAAAAAAAAAAAAAAAAAAAAAA", "AAAAAAAAAAAAAAAAAAAAAAAAAAAAA", "AAAAAAAAAAAAAAAAAAAAAAAAAAAAA", "AAAAAAAAAAAAAAAAAAAAAAAAAAAAA", "AAAAAAAAAAAAAAAAAAAAAAAAAAAAA", "AAAAAAAAAAAAAAAAAAAAAAAAAAAAA", "AAAAAAAAAAAAAAAAAAAAAAAAAAAAA", "AAAAAAAAAAAAAAAAAAAAAAAAAAAAA", "AAAAAAAAAAAAAAAAAAAAAAAAAAAAA", "AAAAAAAAAAAAAAAAAAAAAAAAAAAAA")
        .aisle("AAAAAAAAAAAAABCBAAAAAAAAAAAAA", "AAAAAAAAAAAAAABAAAAAAAAAAAAAA", "AAAAAAAAAAAAAABAAAAAAAAAAAAAA", "AAAAAAAAAAAAABBBAAAAAAAAAAAAA", "AAAAAAAAAAAAABCBAAAAAAAAAAAAA", "AAAAAAAAAAAAABCBAAAAAAAAAAAAA", "AAAAAAAAAAAAABCBAAAAAAAAAAAAA", "AAAAAAAAAAAAAABAAAAAAAAAAAAAA", "AAAAAAAAAAAAAAAAAAAAAAAAAAAAA", "AAAAAAAAAAAAAAAAAAAAAAAAAAAAA", "AAAAAAAAAAAAAAAAAAAAAAAAAAAAA", "AAAAAAAAAAAAAAAAAAAAAAAAAAAAA", "AAAAAAAAAAAAAAAAAAAAAAAAAAAAA", "AAAAAAAAAAAAAAAAAAAAAAAAAAAAA", "AAAAAAAAAAAAAAAAAAAAAAAAAAAAA", "AAAAAAAAAAAAAAAAAAAAAAAAAAAAA", "AAAAAAAAAAAAAAAAAAAAAAAAAAAAA", "AAAAAAAAAAAAAAAAAAAAAAAAAAAAA", "AAAAAAAAAAAAAAAAAAAAAAAAAAAAA", "AAAAAAAAAAAAAAAAAAAAAAAAAAAAA", "AAAAAAAAAAAAAAAAAAAAAAAAAAAAA", "AAAAAAAAAAAAAAAAAAAAAAAAAAAAA", "AAAAAAAAAAAAAAAAAAAAAAAAAAAAA", "AAAAAAAAAAAAAAAAAAAAAAAAAAAAA", "AAAAAAAAAAAAAAAAAAAAAAAAAAAAA", "AAAAAAAAAAAAAAAAAAAAAAAAAAAAA", "AAAAAAAAAAAAAAAAAAAAAAAAAAAAA", "AAAAAAAAAAAAAAAAAAAAAAAAAAAAA", "AAAAAAAAAAAAAAAAAAAAAAAAAAAAA", "AAAAAAAAAAAAAAAAAAAAAAAAAAAAA", "AAAAAAAAAAAAAAAAAAAAAAAAAAAAA", "AAAAAAAAAAAAAAAAAAAAAAAAAAAAA", "AAAAAAAAAAAAAAAAAAAAAAAAAAAAA")
        .aisle("AAAAAAAAAAAABCCCBAAAAAAAAAAAA", "AAAAAAAAAAAAABCBAAAAAAAAAAAAA", "AAAAAAAAAAAAABCBAAAAAAAAAAAAA", "AAAAAAAAAAAAABCBAAAAAAAAAAAAA", "AAAAAAAAAAAAAABAAAAAAAAAAAAAA", "AAAAAAAAAAAAAAAAAAAAAAAAAAAAA", "AAAAAAAAAAAAAAAAAAAAAAAAAAAAA", "AAAAAAAAAAAAAAAAAAAAAAAAAAAAA", "AAAAAAAAAAAAAAAAAAAAAAAAAAAAA", "AAAAAAAAAAAAAAAAAAAAAAAAAAAAA", "AAAAAAAAAAAAAAAAAAAAAAAAAAAAA", "AAAAAAAAAAAAAAAAAAAAAAAAAAAAA", "AAAAAAAAAAAAAAAAAAAAAAAAAAAAA", "AAAAAAAAAAAAAAAAAAAAAAAAAAAAA", "AAAAAAAAAAAAAAAAAAAAAAAAAAAAA", "AAAAAAAAAAAAAAAAAAAAAAAAAAAAA", "AAAAAAAAAAAAAAAAAAAAAAAAAAAAA", "AAAAAAAAAAAAAAAAAAAAAAAAAAAAA", "AAAAAAAAAAAAAAAAAAAAAAAAAAAAA", "AAAAAAAAAAAAAAAAAAAAAAAAAAAAA", "AAAAAAAAAAAAAAAAAAAAAAAAAAAAA", "AAAAAAAAAAAAAAAAAAAAAAAAAAAAA", "AAAAAAAAAAAAAAAAAAAAAAAAAAAAA", "AAAAAAAAAAAAAAAAAAAAAAAAAAAAA", "AAAAAAAAAAAAAAAAAAAAAAAAAAAAA", "AAAAAAAAAAAAAAAAAAAAAAAAAAAAA", "AAAAAAAAAAAAAAAAAAAAAAAAAAAAA", "AAAAAAAAAAAAAAAAAAAAAAAAAAAAA", "AAAAAAAAAAAAAAAAAAAAAAAAAAAAA", "AAAAAAAAAAAAAAAAAAAAAAAAAAAAA", "AAAAAAAAAAAAAAAAAAAAAAAAAAAAA", "AAAAAAAAAAAAAAAAAAAAAAAAAAAAA", "AAAAAAAAAAAAAAAAAAAAAAAAAAAAA")
        .aisle("AAAAAAAAAAAAABCBAAAAAAAAAAAAA", "AAAAAAAAAAAAAABAAAAAAAAAAAAAA", "AAAAAAAAAAAAAAAAAAAAAAAAAAAAA", "AAAAAAAAAAAAAAAAAAAAAAAAAAAAA", "AAAAAAAAAAAAAAAAAAAAAAAAAAAAA", "AAAAAAAAAAAAAAAAAAAAAAAAAAAAA", "AAAAAAAAAAAAAAAAAAAAAAAAAAAAA", "AAAAAAAAAAAAAAAAAAAAAAAAAAAAA", "AAAAAAAAAAAAAAAAAAAAAAAAAAAAA", "AAAAAAAAAAAAAAAAAAAAAAAAAAAAA", "AAAAAAAAAAAAAAAAAAAAAAAAAAAAA", "AAAAAAAAAAAAAAAAAAAAAAAAAAAAA", "AAAAAAAAAAAAAAAAAAAAAAAAAAAAA", "AAAAAAAAAAAAAAAAAAAAAAAAAAAAA", "AAAAAAAAAAAAAAAAAAAAAAAAAAAAA", "AAAAAAAAAAAAAAAAAAAAAAAAAAAAA", "AAAAAAAAAAAAAAAAAAAAAAAAAAAAA", "AAAAAAAAAAAAAAAAAAAAAAAAAAAAA", "AAAAAAAAAAAAAAAAAAAAAAAAAAAAA", "AAAAAAAAAAAAAAAAAAAAAAAAAAAAA", "AAAAAAAAAAAAAAAAAAAAAAAAAAAAA", "AAAAAAAAAAAAAAAAAAAAAAAAAAAAA", "AAAAAAAAAAAAAAAAAAAAAAAAAAAAA", "AAAAAAAAAAAAAAAAAAAAAAAAAAAAA", "AAAAAAAAAAAAAAAAAAAAAAAAAAAAA", "AAAAAAAAAAAAAAAAAAAAAAAAAAAAA", "AAAAAAAAAAAAAAAAAAAAAAAAAAAAA", "AAAAAAAAAAAAAAAAAAAAAAAAAAAAA", "AAAAAAAAAAAAAAAAAAAAAAAAAAAAA", "AAAAAAAAAAAAAAAAAAAAAAAAAAAAA", "AAAAAAAAAAAAAAAAAAAAAAAAAAAAA", "AAAAAAAAAAAAAAAAAAAAAAAAAAAAA", "AAAAAAAAAAAAAAAAAAAAAAAAAAAAA")
           .where("A", Predicates.any())
           .where("B", Predicates.blocks("gtceu:tungsten_carbide_frame"))
           .where("C", Predicates.blocks("gtsac:pressure_resistant_casing").setMinGlobalLimited(470)
                .or(Predicates.abilities(PartAbility.IMPORT_FLUIDS))
                .or(Predicates.abilities(PartAbility.IMPORT_ITEMS))
                .or(Predicates.abilities(PartAbility.EXPORT_ITEMS))
                .or(Predicates.abilities(PartAbility.EXPORT_FLUIDS))
                .or(Predicates.abilities(PartAbility.INPUT_ENERGY).setMaxGlobalLimited(2))
                .or(Predicates.abilities(PartAbility.MAINTENANCE).setExactLimit(1)))
           .where("E", Predicates.blocks("gtceu:extreme_engine_intake_casing"))
           .where("F", Predicates.blocks("gtceu:tungstensteel_firebox_casing"))
           .where("G", Predicates.blocks("gtceu:tungstensteel_pipe_casing"))
           .where("H", Predicates.blocks("gtceu:robust_machine_casing"))
           .where("I", Predicates.blocks("gtceu:tungstensteel_gearbox"))
           .where("J", Predicates.blocks("gtceu:laminated_glass"))
           .where("@", Predicates.controller(Predicates.blocks(definition.get())))
            .build())
        .workableCasingModel('kubejs:block/casing/pressure_resistant_casing', 'gtceu:block/machines/heavy_drilling_rig');
})





























