GTCEuStartupEvents.registry('gtceu:recipe_type', event => {
        event.create('leaching_plant')
            .category('multiblock')
            .setEUIO('in')
            .setMaxIOSize(3, 3, 3, 3)
            .setProgressBar(GuiTextures.PROGRESS_BAR_BATH, FillDirection.UP_TO_DOWN)
            .setSound(GTSoundEntries.BATH)
})



GTCEuStartupEvents.registry('gtceu:machine', event => {
    event.create('leaching_plant', 'multiblock')
        .rotationState(RotationState.ALL)
        .recipeType('leaching_plant')
        .appearanceBlock(GTBlocks.CASING_STEEL_SOLID)
        .recipeModifiers([GTRecipeModifiers.ELECTRIC_OVERCLOCK.apply(OverclockingLogic.NON_PERFECT_OVERCLOCK_SUBTICK), GTRecipeModifiers.BATCH_MODE])
        .pattern(definition => FactoryBlockPattern.start()
        .aisle("BBBBBBBBBBBBBBBBBBB", "AAAAAAAAAAAAAAAAAAA", "AAAAAAAAAAAAAAAAAAA", "AAAAAAAAAAAAAAAAAAA", "AAAAAAAAAAAAAAAAAAA", "AAAAAAAAAAAAAAAAAAA", "AAAAAAAAAAAAAAAAAAA", "AAAAAAAAAAAAAAAAAAA", "AAAAAAAAAAAAAAAAAAA", "AAAAAAAAAAAAAAAAAAA", "AAAAAAAAAAAAAAAAAAA", "AAAAAAAAAAAAAAAAAAA", "AAAAAAAAAAAAAAAAAAA", "AAAAAAAAAAAAAAAAAAA", "AAAAAAAAAAAAAAAAAAA", "AAAAAAAAAAAAAAAAAAA", "AAAAAAAAAAAAAAAAAAA", "AAAAAAAAAAAAAAAAAAA", "AAAAAAAAAAAAAAAAAAA", "AAAAAAAAAAAAAAAAAAA")
        .aisle("BDDDDDDDDDDDDDDDDDB", "AAAAAAAAAAAAAAAAAAA", "AAAAAAAAAAAAAAAAAAA", "AAAAAAAAAAAAAAAAAAA", "AAAAAAAAAAAAAAAAAAA", "AAAAAAAAAAAAAAAAAAA", "AAAAAAAAAAAAAAAAAAA", "AAAAAAAAAAAAAAAAAAA", "AAAAAAAAAAAAAAAAAAA", "AAAAAAAAAAAAAAAAAAA", "AAAAAAAAAAAAAAAAAAA", "AAAAAAAAAAAAAAAAAAA", "AAAAAAAAAAAAAAAAAAA", "AAAAAAAAAAAAAAAAAAA", "AAAAAAAAAAAAAAAAAAA", "AAAAAAAAAAAAAAAAAAA", "AAAAAAAAAAAAAAAAAAA", "AAAAAAAAAAAAAAAAAAA", "AAAAAAAAAAAAAAAAAAA", "AAAAAAAAAAAAAAAAAAA")
        .aisle("BDDDDDDDDDDDDDDDDDB", "AAAAAAAEEEEEAAAAAAA", "AAAAAAAEFFFEAAAAAAA", "AAAAAAAEEEEEAAAAAAA", "AAAAAAAAAAAAAAAAAAA", "AAAAAAAEEEEEAAAAAAA", "AAAAAAAEFFFEAAAAAAA", "AAAAAAAEEEEEAAAAAAA", "AAAAAAAAAAAAAAAAAAA", "AAAAAAAEEEEEAAAAAAA", "AAAAAAAEFFFEAAAAAAA", "AAAAAAAEEEEEAAAAAAA", "AAAAAAAAAAAAAAAAAAA", "AAAAAAAEEEEEAAAAAAA", "AAAAAAAEFFFEAAAAAAA", "AAAAAAAEEEEEAAAAAAA", "AAAAAAAAAAAAAAAAAAA", "AAAAAAAAAAAAAAAAAAA", "AAAAAAAAAAAAAAAAAAA", "AAAAAAAAAAAAAAAAAAA")
        .aisle("BDDDDDDDDDDDDDDDDDB", "AAAAAEEEEEEEEEAAAAA", "AAAAAEEEAAAEEEAAAAA", "AAAAAEEEEEEEEEAAAAA", "AAAAAAAAAAAAAAAAAAA", "AAAAAEEEEEEEEEAAAAA", "AAAAAEEEAAAEEEAAAAA", "AAAAAEEEEEEEEEAAAAA", "AAAAAAAAAAAAAAAAAAA", "AAAAAEEEEEEEEEAAAAA", "AAAAAEEEAAAEEEAAAAA", "AAAAAEEEEEEEEEAAAAA", "AAAAAAAAAAAAAAAAAAA", "AAAAAEEEEEEEEEAAAAA", "AAAAAEEEAAAEEEAAAAA", "AAAAAEEEEEEEEEAAAAA", "AAAAAAAAAAAAAAAAAAA", "AAAAAAAAAAAAAAAAAAA", "AAAAAAAAAAAAAAAAAAA", "AAAAAAAAAAAAAAAAAAA")
        .aisle("BDDDDDDDDDDDDDDDDDB", "AAAAEEEEEEEEEEEAAAA", "AAAAEEAAAGAAAEEAAAA", "AAAAEEEEEHEEEEEAAAA", "AAAAAAAAAHAAAAAAAAA", "AAAAEEEEEHEEEEEAAAA", "AAAAEEAAAAAAAEEAAAA", "AAAAEEEEEHEEEEEAAAA", "AAAAAAAAAHAAAAAAAAA", "AAAAEEEEEHEEEEEAAAA", "AAAAEEAAAAAAAEEAAAA", "AAAAEEEEEHEEEEEAAAA", "AAAAAAAAAHAAAAAAAAA", "AAAAEEEEEHEEEEEAAAA", "AAAAEEAAAAAAAEEAAAA", "AAAAEEEEEEEEEEEAAAA", "AAAAAAAAAAAAAAAAAAA", "AAAAAAAAAAAAAAAAAAA", "AAAAAAAAAAAAAAAAAAA", "AAAAAAAAAAAAAAAAAAA")
        .aisle("BDDDDDDDDDDDDDDDDDB", "AAAEEEEEEEEEEEEEAAA", "AAAEEAAAAGAAAAEEAAA", "AAAEEEEEHHHEEEEEAAA", "AAAAAAAAHHHAAAAAAAA", "AAAEEEEEHHHEEEEEAAA", "AAAEEAAAAGAAAAEEAAA", "AAAEEEEEHHHEEEEEAAA", "AAAAAAAAHHHAAAAAAAA", "AAAEEEEEHHHEEEEEAAA", "AAAEEAAAAGAAAAEEAAA", "AAAEEEEEHHHEEEEEAAA", "AAAAAAAAHHHAAAAAAAA", "AAAEEEEEHHHEEEEEAAA", "AAAEEAAAAGAAAAEEAAA", "AAAEEEEEEEEEEEEEAAA", "AAAAAAAAAAAAAAAAAAA", "AAAAAAAAIIIAAAAAAAA", "AAAAAAAAIIIAAAAAAAA", "AAAAAAAAIIIAAAAAAAA")
        .aisle("BDDDDDDDDDDDDDDDDDB", "AAAEEEEEEEEEEEEEAAA", "AAAEAAAAAGAAAAAEAAA", "AAAEEEEEEHEEEEEEAAA", "AAAAAAAAAHAAAAAAAAA", "AAAEEEEEEHEEEEEEAAA", "AAAEAAAAAGAAAAAEAAA", "AAAEEEEEEHEEEEEEAAA", "AAAAAAAAAHAAAAAAAAA", "AAAEEEEEEHEEEEEEAAA", "AAAEAAAAAGAAAAAEAAA", "AAAEEEEEEHEEEEEEAAA", "AAAAAAAAAHAAAAAAAAA", "AAAEEEEEEHEEEEEEAAA", "AAAEAAAAAGAAAAAEAAA", "AAAEEEEEEHEEEEEEAAA", "AAAAAAAAAHAAAAAAAAA", "AAAAAAIIIHIIIAAAAAA", "AAAAAAIIIHIIIAAAAAA", "AAAAAAIIIIIIIAAAAAA")
        .aisle("BDDDDDDDDDDDDDDDDDB", "AAEEEEEEEEEEEEEEEAA", "AAEEAAAAAGAAAAAEEAA", "AAEEEEEEEEEEEEEEEAA", "AAAAAAAAAAAAAAAAAAA", "AAEEEEEEEEEEEEEEEAA", "AAEEAAAAAGAAAAAEEAA", "AAEEEEEEEEEEEEEEEAA", "AAAAAAAAAAAAAAAAAAA", "AAEEEEEEEEEEEEEEEAA", "AAEEAAAAAGAAAAAEEAA", "AAEEEEEEEEEEEEEEEAA", "AAAAAAAAAAAAAAAAAAA", "AAEEEEEEEEEEEEEEEAA", "AAEEAAAAAGAAAAAEEAA", "AAEEEEEEEEEEEEEEEAA", "AAAAAAAAAAAAAAAAAAA", "AAAAAAIIIIIIIAAAAAA", "AAAAAAIAAJAAIAAAAAA", "AAAAAAIIIIIIIAAAAAA")
        .aisle("BDDDDDDDDDDDDDDDDDB", "AAEEEEEEEEEEEEEEEAA", "AAFAAAAAAGAAAAAAFAA", "AAEEEHEEEEEEEHEEEAA", "AAAAAHAAAAAAAHAAAAA", "AAEEEHEEEEEEEHEEEAA", "AAFAAAAAAGAAAAAAFAA", "AAEEEHEEEEEEEHEEEAA", "AAAAAHAAAAAAAHAAAAA", "AAEEEHEEEEEEEHEEEAA", "AAFAAAAAAGAAAAAAFAA", "AAEEEHEEEEEEEHEEEAA", "AAAAAHAAAAAAAHAAAAA", "AAEEEHEEEEEEEHEEEAA", "AAFAAAAAAGAAAAAAFAA", "AAEEEEEEEEEEEEEEEAA", "AAAAAAAAAAAAAAAAAAA", "AAAAAIIIIIIIIIAAAAA", "AAAAAIIAAJAAIIAAAAA", "AAAAAIIIIIIIIIAAAAA")
        .aisle("BDDDDDDDDDDDDDDDDDB", "AAEEEEEEEEEEEEEEEAA", "AAFAGGGGGKGGGGGAFAA", "AAEEHHHEEKEEHHHEEAA", "AAAAHHHAAKAAHHHAAAA", "AAEEHHHEEKEEHHHEEAA", "AAFAAGGGGKGGGGGAFAA", "AAEEHHHEEKEEHHHEEAA", "AAAAHHHAAKAAHHHAAAA", "AAEEHHHEEKEEHHHEEAA", "AAFAAGGGGKGGGGGAFAA", "AAEEHHHEEKEEHHHEEAA", "AAAAHHHAAKAAHHHAAAA", "AAEEHHHEEKEEHHHEEAA", "AAFAAGGGGKGGGGGAFAA", "AAEEEEHEEKEEHEEEEAA", "AAAAAAHAAKAAHAAAAAA", "AAAAAIHIIKIIHIAAAAA", "AAAAAIHJJKJJHIAAAAA", "AAAAAIIIIIIIIIAAAAA")
        .aisle("BDDDDDDDDDDDDDDDDDB", "AAEEEEEEEEEEEEEEEAA", "AAFAAAAAAGAAAAAAFAA", "AAEEEHEEEEEEEHEEEAA", "AAAAAHAAAAAAAHAAAAA", "AAEEEHEEEEEEEHEEEAA", "AAFAAAAAAGAAAAAAFAA", "AAEEEHEEEEEEEHEEEAA", "AAAAAHAAAAAAAHAAAAA", "AAEEEHEEEEEEEHEEEAA", "AAFAAAAAAGAAAAAAFAA", "AAEEEHEEEEEEEHEEEAA", "AAAAAHAAAAAAAHAAAAA", "AAEEEHEEEEEEEHEEEAA", "AAFAAAAAAGAAAAAAFAA", "AAEEEEEEEEEEEEEEEAA", "AAAAAAAAAAAAAAAAAAA", "AAAAAIIIIIIIIIAAAAA", "AAAAAIIAAJAAIIAAAAA", "AAAAAIIIIIIIIIAAAAA")
        .aisle("BDDDDDDDDDDDDDDDDDB", "AAEEEEEEEEEEEEEEEAA", "AAEEAAAAAGAAAAAEEAA", "AAEEEEEEEEEEEEEEEAA", "AAAAAAAAAAAAAAAAAAA", "AAEEEEEEEEEEEEEEEAA", "AAEEAAAAAGAAAAAEEAA", "AAEEEEEEEEEEEEEEEAA", "AAAAAAAAAAAAAAAAAAA", "AAEEEEEEEEEEEEEEEAA", "AAEEAAAAAGAAAAAEEAA", "AAEEEEEEEEEEEEEEEAA", "AAAAAAAAAAAAAAAAAAA", "AAEEEEEEEEEEEEEEEAA", "AAEEAAAAAGAAAAAEEAA", "AAEEEEEEEEEEEEEEEAA", "AAAAAAAAAAAAAAAAAAA", "AAAAAAIIIIIIIAAAAAA", "AAAAAAIAAJAAIAAAAAA", "AAAAAAIIIIIIIAAAAAA")
        .aisle("BDDDDDDDDDDDDDDDDDB", "AAAEEEEEEEEEEEEEAAA", "AAAEAAAAAGAAAAAEAAA", "AAAEEEEEEHEEEEEEAAA", "AAAAAAAAAHAAAAAAAAA", "AAAEEEEEEHEEEEEEAAA", "AAAEAAAAAGAAAAAEAAA", "AAAEEEEEEHEEEEEEAAA", "AAAAAAAAAHAAAAAAAAA", "AAAEEEEEEHEEEEEEAAA", "AAAEAAAAAGAAAAAEAAA", "AAAEEEEEEHEEEEEEAAA", "AAAAAAAAAHAAAAAAAAA", "AAAEEEEEEHEEEEEEAAA", "AAAEAAAAAGAAAAAEAAA", "AAAEEEEEEHEEEEEEAAA", "AAAAAAAAAHAAAAAAAAA", "AAAAAAIIIHIIIAAAAAA", "AAAAAAIIIHIIIAAAAAA", "AAAAAAIIIIIIIAAAAAA")
        .aisle("BDDDDDDDDDDDDDDDDDB", "AAAEEEEEEEEEEEEEAAA", "AAAEEAAAAGAAAAEEAAA", "AAAEEEEEHHHEEEEEAAA", "AAAAAAAAHHHAAAAAAAA", "AAAEEEEEHHHEEEEEAAA", "AAAEEAAAAGAAAAEEAAA", "AAAEEEEEHHHEEEEEAAA", "AAAAAAAAHHHAAAAAAAA", "AAAEEEEEHHHEEEEEAAA", "AAAEEAAAAGAAAAEEAAA", "AAAEEEEEHHHEEEEEAAA", "AAAAAAAAHHHAAAAAAAA", "AAAEEEEEHHHEEEEEAAA", "AAAEEAAAAGAAAAEEAAA", "AAAEEEEEEEEEEEEEAAA", "AAAAAAAAAAAAAAAAAAA", "AAAAAAAAIIIAAAAAAAA", "AAAAAAAAIIIAAAAAAAA", "AAAAAAAAIIIAAAAAAAA")
        .aisle("BDDDDDDDDDDDDDDDDDB", "AAAAEEEEEEEEEEEAAAA", "AAAAEEAAAGAAAEEAAAA", "AAAAEEEEEHEEEEEAAAA", "AAAAAAAAAHAAAAAAAAA", "AAAAEEEEEHEEEEEAAAA", "AAAAEEAAAAAAAEEAAAA", "AAAAEEEEEHEEEEEAAAA", "AAAAAAAAAHAAAAAAAAA", "AAAAEEEEEHEEEEEAAAA", "AAAAEEAAAAAAAEEAAAA", "AAAAEEEEEHEEEEEAAAA", "AAAAAAAAAHAAAAAAAAA", "AAAAEEEEEHEEEEEAAAA", "AAAAEEAAAAAAAEEAAAA", "AAAAEEEEEEEEEEEAAAA", "AAAAAAAAAAAAAAAAAAA", "AAAAAAAAAAAAAAAAAAA", "AAAAAAAAAAAAAAAAAAA", "AAAAAAAAAAAAAAAAAAA")
        .aisle("BDDDDDDDDDDDDDDDDDB", "AAAAAEEEEEEEEEAAAAA", "AAAAAEEEAAAEEEAAAAA", "AAAAAEEEEEEEEEAAAAA", "AAAAAAAAAAAAAAAAAAA", "AAAAAEEEEEEEEEAAAAA", "AAAAAEEEAAAEEEAAAAA", "AAAAAEEEEEEEEEAAAAA", "AAAAAAAAAAAAAAAAAAA", "AAAAAEEEEEEEEEAAAAA", "AAAAAEEEAAAEEEAAAAA", "AAAAAEEEEEEEEEAAAAA", "AAAAAAAAAAAAAAAAAAA", "AAAAAEEEEEEEEEAAAAA", "AAAAAEEEAAAEEEAAAAA", "AAAAAEEEEEEEEEAAAAA", "AAAAAAAAAAAAAAAAAAA", "AAAAAAAAAAAAAAAAAAA", "AAAAAAAAAAAAAAAAAAA", "AAAAAAAAAAAAAAAAAAA")
        .aisle("BDDDDDDDDDDDDDDDDDB", "AAAAAAAEEEEEAAAAAAA", "AAAAAAAEFFFEAAAAAAA", "AAAAAAAEEEEEAAAAAAA", "AAAAAAAAAAAAAAAAAAA", "AAAAAAAEEEEEAAAAAAA", "AAAAAAAEFFFEAAAAAAA", "AAAAAAAEEEEEAAAAAAA", "AAAAAAAAAAAAAAAAAAA", "AAAAAAAEEEEEAAAAAAA", "AAAAAAAEFFFEAAAAAAA", "AAAAAAAEEEEEAAAAAAA", "AAAAAAAAAAAAAAAAAAA", "AAAAAAAEEEEEAAAAAAA", "AAAAAAAEFFFEAAAAAAA", "AAAAAAAEEEEEAAAAAAA", "AAAAAAAAAAAAAAAAAAA", "AAAAAAAAAAAAAAAAAAA", "AAAAAAAAAAAAAAAAAAA", "AAAAAAAAAAAAAAAAAAA")
        .aisle("BDDDDDDDDDDDDDDDDDB", "AAAAAAAAAAAAAAAAAAA", "AAAAAAAAAAAAAAAAAAA", "AAAAAAAAAAAAAAAAAAA", "AAAAAAAAAAAAAAAAAAA", "AAAAAAAAAAAAAAAAAAA", "AAAAAAAAAAAAAAAAAAA", "AAAAAAAAAAAAAAAAAAA", "AAAAAAAAAAAAAAAAAAA", "AAAAAAAAAAAAAAAAAAA", "AAAAAAAAAAAAAAAAAAA", "AAAAAAAAAAAAAAAAAAA", "AAAAAAAAAAAAAAAAAAA", "AAAAAAAAAAAAAAAAAAA", "AAAAAAAAAAAAAAAAAAA", "AAAAAAAAAAAAAAAAAAA", "AAAAAAAAAAAAAAAAAAA", "AAAAAAAAAAAAAAAAAAA", "AAAAAAAAAAAAAAAAAAA", "AAAAAAAAAAAAAAAAAAA")
        .aisle("BBBBBBBBBLBBBBBBBBB", "AAAAAAAAAAAAAAAAAAA", "AAAAAAAAAAAAAAAAAAA", "AAAAAAAAAAAAAAAAAAA", "AAAAAAAAAAAAAAAAAAA", "AAAAAAAAAAAAAAAAAAA", "AAAAAAAAAAAAAAAAAAA", "AAAAAAAAAAAAAAAAAAA", "AAAAAAAAAAAAAAAAAAA", "AAAAAAAAAAAAAAAAAAA", "AAAAAAAAAAAAAAAAAAA", "AAAAAAAAAAAAAAAAAAA", "AAAAAAAAAAAAAAAAAAA", "AAAAAAAAAAAAAAAAAAA", "AAAAAAAAAAAAAAAAAAA", "AAAAAAAAAAAAAAAAAAA", "AAAAAAAAAAAAAAAAAAA", "AAAAAAAAAAAAAAAAAAA", "AAAAAAAAAAAAAAAAAAA", "AAAAAAAAAAAAAAAAAAA")
           .where("A", Predicates.any())
           .where("B", Predicates.blocks("gtceu:solid_machine_casing").setMinGlobalLimited(70)
                .or(Predicates.abilities(PartAbility.IMPORT_FLUIDS))
                .or(Predicates.abilities(PartAbility.IMPORT_ITEMS))
                .or(Predicates.abilities(PartAbility.EXPORT_ITEMS))
                .or(Predicates.abilities(PartAbility.EXPORT_FLUIDS))
                .or(Predicates.abilities(PartAbility.INPUT_ENERGY).setMaxGlobalLimited(2))
                .or(Predicates.abilities(PartAbility.MAINTENANCE).setExactLimit(1)))
           .where("D", Predicates.blocks("gtceu:light_concrete"))
           .where("E", Predicates.blocks("gtceu:corrosion_proof_casing"))
           .where("F", Predicates.blocks("gtceu:laminated_glass"))
           .where("G", Predicates.blocks("gtceu:steel_pipe_casing"))
           .where("H", Predicates.blocks("gtceu:titanium_pipe_casing"))
           .where("I", Predicates.blocks("gtceu:solid_machine_casing"))
           .where("J", Predicates.blocks("gtceu:steel_frame"))
           .where("K", Predicates.blocks("gtceu:steel_gearbox"))
           .where("L", Predicates.controller(Predicates.blocks(definition.get())))
            .build())
        .workableCasingModel('gtceu:block/casings/solid/machine_casing_solid_steel', 'gtceu:block/machines/chemical_reactor');
})





























