GTCEuStartupEvents.registry('gtceu:recipe_type', event => {
        event.create('heavy_drilling_rig')
            .category('multiblock')
            .setEUIO('in')
            .setMaxIOSize(2, 1, 3, 3)
            .setProgressBar($GTSACGuiTextures.PROGRESS_BAR_DRILL, FillDirection.UP_TO_DOWN)
            .setSound(GTSoundEntries.MACERATOR)
})



GTCEuStartupEvents.registry('gtceu:machine', event => {
    event.create('heavy_drilling_rig', 'multiblock')
        .rotationState(RotationState.ALL)
        .recipeType('heavy_drilling_rig')
        .appearanceBlock(GTBlocks.CASING_STEEL_SOLID)
        .recipeModifiers([GTRecipeModifiers.ELECTRIC_OVERCLOCK.apply(OverclockingLogic.NON_PERFECT_OVERCLOCK_SUBTICK), GTRecipeModifiers.BATCH_MODE])
        .pattern(definition => FactoryBlockPattern.start()
        .aisle("AAAAAAACAAAAAAA", "AAAAAAADAAAAAAA", "AAAAAAADAAAAAAA", "AAAAAAADAAAAAAA", "AAAAAAAAAAAAAAA", "AAAAAAAAAAAAAAA", "AAAAAAAAAAAAAAA", "AAAAAAAAAAAAAAA", "AAAAAAAAAAAAAAA", "AAAAAAAAAAAAAAA", "AAAAAAAAAAAAAAA", "AAAAAAAAAAAAAAA", "AAAAAAAAAAAAAAA", "AAAAAAAAAAAAAAA", "AAAAAAAAAAAAAAA", "AAAAAAAAAAAAAAA")
        .aisle("AAAAAACCCAAAAAA", "AAAAAADEDAAAAAA", "AAAAAADEDAAAAAA", "AAAAAADEDAAAAAA", "AAAAAAADAAAAAAA", "AAAAAAADAAAAAAA", "AAAAAAADAAAAAAA", "AAAAAAAAAAAAAAA", "AAAAAAAAAAAAAAA", "AAAAAAAAAAAAAAA", "AAAAAAAAAAAAAAA", "AAAAAAAAAAAAAAA", "AAAAAAAAAAAAAAA", "AAAAAAAAAAAAAAA", "AAAAAAAAAAAAAAA", "AAAAAAAAAAAAAAA")
        .aisle("AAAAAAACAAAAAAA", "AAAAAAADAAAAAAA", "AAAAAAADAAAAAAA", "AAAAAAADAAAAAAA", "AAAAAADEDAAAAAA", "AAAAAADEDAAAAAA", "AAAAAADEDAAAAAA", "AAAAAAADAAAAAAA", "AAAAAAAAAAAAAAA", "AAAAAAAAAAAAAAA", "AAAAAAAAAAAAAAA", "AAAAAAAAAAAAAAA", "AAAAAAAAAAAAAAA", "AAAAAAAAAAAAAAA", "AAAAAAAAAAAAAAA", "AAAAAAAAAAAAAAA")
        .aisle("AAAAAAAAAAAAAAA", "AAAAAAAAAAAAAAA", "AAAAAAAAAAAAAAA", "AAAAAAAAAAAAAAA", "AAAAAAADAAAAAAA", "AAAAAAADAAAAAAA", "AAAAAAADAAAAAAA", "AAAAAADEDAAAAAA", "AAAAAAADAAAAAAA", "AAAAAAAAAAAAAAA", "AAAAAAAAAAAAAAA", "AAAAAAAAAAAAAAA", "AAAAAAAAAAAAAAA", "AAAAAAAAAAAAAAA", "AAAAAAAAAAAAAAA", "AAAAAAAAAAAAAAA")
        .aisle("AAAAAAAAAAAAAAA", "AAAAAAAAAAAAAAA", "AAAAAAAAAAAAAAA", "AAAAAAAAAAAAAAA", "AAAAAAAAAAAAAAA", "AAAAAAAAAAAAAAA", "AAAAAAAAAAAAAAA", "AAAAAAADAAAAAAA", "AAAAAADEDAAAAAA", "AAAAAAADAAAAAAA", "AAAAAAAFAAAAAAA", "AAAAAAFFFAAAAAA", "AAAAAAFGFAAAAAA", "AAAAAAFGFAAAAAA", "AAAAAAFGFAAAAAA", "AAAAAAFFFAAAAAA")
        .aisle("AAAAAAAAAAAAAAA", "AAAAAAAAAAAAAAA", "AAAAAAAAAAAAAAA", "AAAAAAAAAAAAAAA", "AAAAAAAAAAAAAAA", "AAAAAAAAAAAAAAA", "AAAAAAAAAAAAAAA", "AAAAAAAAAAAAAAA", "AAAAAAADAAAAAAA", "AAAAAAAHAAAAAAA", "AAAAAAFFFAAAAAA", "AAAAAFFAFFAAAAA", "AAAAAEAAAEAAAAA", "AAAAAEAAAEAAAAA", "AAAAAEAAAEAAAAA", "AAAAAFFFFFAAAAA")
        .aisle("ACAAAAAAAAAAACA", "ADAAAAACAAAAADA", "ADAAAAACAAAAADA", "ADAAAAFFFAAAADA", "AADAAAFEFAAADAA", "AADAAADGDAAADAA", "AADAAADGDAAADAA", "AAADAADGDAADAAA", "AAAADADFDADAAAA", "AAAAAAFHFAAAAAA", "AAAAAFFFFFAAAAA", "AAAAFFAAAFFAAAA", "AAAAFAAAAAFAAAA", "AAAAFAAAAAFAAAA", "AAAAFAAAAAFAAAA", "AAAAFFFFFFFAAAA")
        .aisle("CCCAAAACAAAACCC", "DEDAAACHCAAADED", "DEDAAACHCAAADED", "DEDAAAFHFAAADED", "ADEDAAEHEAADEDA", "ADEDAAGHGAADEDA", "ADEDAAGHGAADEDA", "AADEDAGHGADEDAA", "AAADEDFHFDEDAAA", "AAAADHHHHHDAAAA", "AAAAFFFHFFFAAAA", "AAAAFAAAAAFAAAA", "AAAAGAAAAAGAAAA", "AAAAGAAAAAGAAAA", "AAAAGAAAAAGAAAA", "AAAAFFFFFFFAAAA")
        .aisle("ACAAAAAAAAAAACA", "ADAAAAACAAAAADA", "ADAAAAACAAAAADA", "ADAAAAFFFAAAADA", "AADAAAF@FAAADAA", "AADAAADGDAAADAA", "AADAAADGDAAADAA", "AAADAADGDAADAAA", "AAAADADFDADAAAA", "AAAAAAFHFAAAAAA", "AAAAAFFFFFAAAAA", "AAAAFFAAAFFAAAA", "AAAAFAAAAAFAAAA", "AAAAFAAAAAFAAAA", "AAAAFAAAAAFAAAA", "AAAAFFFFFFFAAAA")
        .aisle("AAAAAAAAAAAAAAA", "AAAAAAAAAAAAAAA", "AAAAAAAAAAAAAAA", "AAAAAAAAAAAAAAA", "AAAAAAAAAAAAAAA", "AAAAAAAAAAAAAAA", "AAAAAAAAAAAAAAA", "AAAAAAAAAAAAAAA", "AAAAAAADAAAAAAA", "AAAAAAAHAAAAAAA", "AAAAAAFFFAAAAAA", "AAAAAFFAFFAAAAA", "AAAAAEAAAEAAAAA", "AAAAAEAAAEAAAAA", "AAAAAEAAAEAAAAA", "AAAAAFFFFFAAAAA")
        .aisle("AAAAAAAAAAAAAAA", "AAAAAAAAAAAAAAA", "AAAAAAAAAAAAAAA", "AAAAAAAAAAAAAAA", "AAAAAAAAAAAAAAA", "AAAAAAAAAAAAAAA", "AAAAAAAAAAAAAAA", "AAAAAAADAAAAAAA", "AAAAAADEDAAAAAA", "AAAAAAADAAAAAAA", "AAAAAAAFAAAAAAA", "AAAAAAFFFAAAAAA", "AAAAAAFGFAAAAAA", "AAAAAAFGFAAAAAA", "AAAAAAFGFAAAAAA", "AAAAAAFFFAAAAAA")
        .aisle("AAAAAAAAAAAAAAA", "AAAAAAAAAAAAAAA", "AAAAAAAAAAAAAAA", "AAAAAAAAAAAAAAA", "AAAAAAADAAAAAAA", "AAAAAAADAAAAAAA", "AAAAAAADAAAAAAA", "AAAAAADEDAAAAAA", "AAAAAAADAAAAAAA", "AAAAAAAAAAAAAAA", "AAAAAAAAAAAAAAA", "AAAAAAAAAAAAAAA", "AAAAAAAAAAAAAAA", "AAAAAAAAAAAAAAA", "AAAAAAAAAAAAAAA", "AAAAAAAAAAAAAAA")
        .aisle("AAAAAAACAAAAAAA", "AAAAAAADAAAAAAA", "AAAAAAADAAAAAAA", "AAAAAAADAAAAAAA", "AAAAAADEDAAAAAA", "AAAAAADEDAAAAAA", "AAAAAADEDAAAAAA", "AAAAAAADAAAAAAA", "AAAAAAAAAAAAAAA", "AAAAAAAAAAAAAAA", "AAAAAAAAAAAAAAA", "AAAAAAAAAAAAAAA", "AAAAAAAAAAAAAAA", "AAAAAAAAAAAAAAA", "AAAAAAAAAAAAAAA", "AAAAAAAAAAAAAAA")
        .aisle("AAAAAACCCAAAAAA", "AAAAAADEDAAAAAA", "AAAAAADEDAAAAAA", "AAAAAADEDAAAAAA", "AAAAAAADAAAAAAA", "AAAAAAADAAAAAAA", "AAAAAAADAAAAAAA", "AAAAAAAAAAAAAAA", "AAAAAAAAAAAAAAA", "AAAAAAAAAAAAAAA", "AAAAAAAAAAAAAAA", "AAAAAAAAAAAAAAA", "AAAAAAAAAAAAAAA", "AAAAAAAAAAAAAAA", "AAAAAAAAAAAAAAA", "AAAAAAAAAAAAAAA")
        .aisle("AAAAAAACAAAAAAA", "AAAAAAADAAAAAAA", "AAAAAAADAAAAAAA", "AAAAAAADAAAAAAA", "AAAAAAAAAAAAAAA", "AAAAAAAAAAAAAAA", "AAAAAAAAAAAAAAA", "AAAAAAAAAAAAAAA", "AAAAAAAAAAAAAAA", "AAAAAAAAAAAAAAA", "AAAAAAAAAAAAAAA", "AAAAAAAAAAAAAAA", "AAAAAAAAAAAAAAA", "AAAAAAAAAAAAAAA", "AAAAAAAAAAAAAAA", "AAAAAAAAAAAAAAA")
           .where("A", Predicates.any())
            .where("@", Predicates.controller(Predicates.blocks(definition.get())))
           .where("C", Predicates.blocks("gtceu:steel_machine_casing"))
           .where("D", Predicates.blocks("gtceu:steel_frame"))
           .where("E", Predicates.blocks("gtceu:steel_gearbox"))
           .where("F", Predicates.blocks("gtceu:solid_machine_casing")
                .or(Predicates.abilities(PartAbility.IMPORT_FLUIDS))
                .or(Predicates.abilities(PartAbility.IMPORT_ITEMS))
                .or(Predicates.abilities(PartAbility.EXPORT_FLUIDS))
                .or(Predicates.abilities(PartAbility.EXPORT_ITEMS))
                .or(Predicates.abilities(PartAbility.INPUT_ENERGY).setMaxGlobalLimited(2))
                .or(Predicates.abilities(PartAbility.MAINTENANCE).setExactLimit(1)))
           .where("G", Predicates.blocks("gtceu:steel_firebox_casing"))
           .where("H", Predicates.blocks("gtceu:steel_pipe_casing"))
            .build())
        .workableCasingModel('gtceu:block/casings/solid/machine_casing_solid_steel', 'gtceu:block/machines/heavy_drilling_rig');
})
