GTCEuStartupEvents.registry('gtceu:recipe_type', event => {
        event.create('froth_flotation_plant')
            .category('multiblock')
            .setEUIO('in')
            .setMaxIOSize(3, 3, 3, 2)
            .setProgressBar(GuiTextures.PROGRESS_BAR_BATH, FillDirection.UP_TO_DOWN)
            .setSound(GTSoundEntries.BATH)
})



GTCEuStartupEvents.registry('gtceu:machine', event => {
    event.create('froth_flotation_plant', 'multiblock')
        .rotationState(RotationState.ALL)
        .recipeType('froth_flotation_plant')
        .appearanceBlock(GTBlocks.CASING_STEEL_SOLID)
        .recipeModifiers([GTRecipeModifiers.ELECTRIC_OVERCLOCK.apply(OverclockingLogic.NON_PERFECT_OVERCLOCK_SUBTICK), GTRecipeModifiers.BATCH_MODE])
        .pattern(definition => FactoryBlockPattern.start()
        .aisle("BBBBBBBBBBBBBBBBBBBBBBBBBBBBBBBBBBBBBBBBBBB", "AAAAAAAAAAAAAAAAAAAAAAAAAAAAAAAAAAAAAAAAAAA", "AAAAAAAAAAAAAAAAAAAAAAAAAAAAAAAAAAAAAAAAAAA", "AAAAAAAAAAAAAAAAAAAAAAAAAAAAAAAAAAAAAAAAAAA", "AAAAAAAAAAAAAAAAAAAAAAAAAAAAAAAAAAAAAAAAAAA", "AAAAAAAAAAAAAAAAAAAAAAAAAAAAAAAAAAAAAAAAAAA", "AAAAAAAAAAAAAAAAAAAAAAAAAAAAAAAAAAAAAAAAAAA", "AAAAAAAAAAAAAAAAAAAAAAAAAAAAAAAAAAAAAAAAAAA", "AAAAAAAAAAAAAAAAAAAAAAAAAAAAAAAAAAAAAAAAAAA", "AAAAAAAAAAAAAAAAAAAAAAAAAAAAAAAAAAAAAAAAAAA", "AAAAAAAAAAAAAAAAAAAAAAAAAAAAAAAAAAAAAAAAAAA")
        .aisle("BDDDDDDDDDDDDDDDDDDDDDDDDDDDDDDDDDDDDDDDDDB", "AAAAAAAAAAAAAAAAAAAAAAAAAAAAAAAAAAAAAAAAAAA", "AAAAAAAAAAAAAAAAAAAAAAAAAAAAAAAAAAAAAAAAAAA", "AAAAAAAAAAAAAAAAAAAAAAAAAAAAAAAAAAAAAAAAAAA", "AAAAAAAAAAAAAAAAAAAAAAAAAAAAAAAAAAAAAAAAAAA", "AAAAAAAAAAAAAAAAAAAAAAAAAAAAAAAAAAAAAAAAAAA", "AAAAAAAAAAAAAAAAAAAAAAAAAAAAAAAAAAAAAAAAAAA", "AAAAAAAAAAAAAAAAAAAAAAAAAAAAAAAAAAAAAAAAAAA", "AAAAAAAAAAAAAAAAAAAAAAAAAAAAAAAAAAAAAAAAAAA", "AAAAAAAAAAAAAAAAAAAAAAAAAAAAAAAAAAAAAAAAAAA", "AAAAAAAAAAAAAAAAAAAAAAAAAAAAAAAAAAAAAAAAAAA")
        .aisle("BDDDDDDDDDDDDDDDDDDDDDDDDDDDDDDDDDDDDDDDDDB", "AAAAAAEEEAAAAAAAAAAAEEEAAAAAAAAAAAEEEAAAAAA", "AAAAAAEFEAAAAAAAAAAAEFEAAAAAAAAAAAEFEAAAAAA", "AAAAAAEEEAAAAAAAAAAAEEEAAAAAAAAAAAEEEAAAAAA", "AAAAAAEEEAAAAAAAAAAAEEEAAAAAAAAAAAEEEAAAAAA", "AAAAAAEEEAAAAAAAAAAAEEEAAAAAAAAAAAEEEAAAAAA", "AAAAAAEEEAAAAAAAAAAAEEEAAAAAAAAAAAEEEAAAAAA", "AAAAAAEEEAAAAAAAAAAAEEEAAAAAAAAAAAEEEAAAAAA", "AAAAAAEEEAAAAAAAAAAAEEEAAAAAAAAAAAEEEAAAAAA", "AAAAAAEEEAAAAAAAAAAAEEEAAAAAAAAAAAEEEAAAAAA", "AAAAAAAGAAAAAAAAAAAAAGAAAAAAAAAAAAAGAAAAAAA")
        .aisle("BDDDDDDDDDDDDDDDDDDDDDDDDDDDDDDDDDDDDDDDDDB", "AAAAEEEEEEEAAAAAAAEEEEEEEAAAAAAAEEEEEEEAAAA", "AAAAEEAAAEEAAAAAAAEEAAAEEAAAAAAAEEAAAEEAAAA", "AAAAEEAAAEEAAAAAAAEEAAAEEAAAAAAAEEAAAEEAAAA", "AAAAEEAAAEEAAAAAAAEEAAAEEAAAAAAAEEAAAEEAAAA", "AAAAEEAAAEEAAAAAAAEEAAAEEAAAAAAAEEAAAEEAAAA", "AAAAEEAAAEEAAAAAAAEEAAAEEAAAAAAAEEAAAEEAAAA", "AAAAEEAAAEEAAAAAAAEEAAAEEAAAAAAAEEAAAEEAAAA", "AAAAEEAAAEEAAAAAAAEEAAAEEAAAAAAAEEAAAEEAAAA", "AAAAEEAAAEEAAAAAAAEEAAAEEAAAAAAAEEAAAEEAAAA", "AAAAAAAGAAAAAAAAAAAAAGAAAAAAAAAAAAAGAAAAAAA")
        .aisle("BDDDDDDDDDDDDDDDDDDDDDDDDDDDDDDDDDDDDDDDDDB", "AAAEEEEEEEEEAAAAAEEEEEEEEEAAAAAEEEEEEEEEAAA", "AAAEAAAAAAAEAAAAAEAAAAAAAEAAAAAEAAAAAAAEAAA", "AAAEAAAHAAAEAAAAAEAAAHAAAEAAAAAEAAAHAAAEAAA", "AAAEAAAAAAAEAAAAAEAAAAAAAEAAAAAEAAAAAAAEAAA", "AAAEAAAAAAAEAAAAAEAAAAAAAEAAAAAEAAAAAAAEAAA", "AAAEAAAAAAAEAAAAAEAAAAAAAEAAAAAEAAAAAAAEAAA", "AAAEAAAAAAAEAAAAAEAAAAAAAEAAAAAEAAAAAAAEAAA", "AAAEAAAAAAAEAAAAAEAAAAAAAEAAAAAEAAAAAAAEAAA", "AAAEAAAAAAAEAAAAAEAAAAAAAEAAAAAEAAAAAAAEAAA", "AAAAAAAGAAAAAAAAAAAAAGAAAAAAAAAAAAAGAAAAAAA")
        .aisle("BDDDDDDDDDDDDDDDDDDDDDDDDDDDDDDDDDDDDDDDDDB", "AAAEEEEEEEEEAAAAAEEEEEEEEEAAAAAEEEEEEEEEAAA", "AAAEAAAAAAAEAAAAAEAAAAAAAEAAAAAEAAAAAAAEAAA", "AAAEAAAHAAAEAAAAAEAAAHAAAEAAAAAEAAAHAAAEAAA", "AAAEAAAAAAAEAAAAAEAAAAAAAEAAAAAEAAAAAAAEAAA", "AAAEAAAAAAAEAAAAAEAAAAAAAEAAAAAEAAAAAAAEAAA", "AAAEAAAAAAAEAAAAAEAAAAAAAEAAAAAEAAAAAAAEAAA", "AAAEAAAAAAAEAAAAAEAAAAAAAEAAAAAEAAAAAAAEAAA", "AAAEAAAAAAAEAAAAAEAAAAAAAEAAAAAEAAAAAAAEAAA", "AAAEAAAAAAAEAAAAAEAAAAAAAEAAAAAEAAAAAAAEAAA", "AAAAAAAGAAAAAAAAAAAAAGAAAAAAAAAAAAAGAAAAAAA")
        .aisle("BDDDDDDDDDDDDDDDDDDDDDDDDDDDDDDDDDDDDDDDDDB", "AAEEEEEEEEEEEAAAEEEEEEEEEEEAAAEEEEEEEEEEEAA", "AAEAAAAAAAAAEAAAEAAAAAAAAAEAAAEAAAAAAAAAEAA", "AAEAAAAHAAAAEAAAEAAAAHAAAAEAAAEAAAAHAAAAEAA", "AAEAAAAAAAAAEAAAEAAAAAAAAAEAAAEAAAAAAAAAEAA", "AAEAAAAAAAAAEAAAEAAAAAAAAAEAAAEAAAAAAAAAEAA", "AAEAAAAAAAAAEAAAEAAAAAAAAAEAAAEAAAAAAAAAEAA", "AAEAAAAAAAAAEAAAEAAAAAAAAAEAAAEAAAAAAAAAEAA", "AAEAAAAAAAAAEAAAEAAAAAAAAAEAAAEAAAAAAAAAEAA", "AAEAAAAAAAAAEAAAEAAAAAAAAAEAAAEAAAAAAAAAEAA", "AAAAAAAGAAAAAAAAAAAAAGAAAAAAAAAAAAAGAAAAAAA")
        .aisle("BDDDDDDDDDDDDDDDDDDDDDDDDDDDDDDDDDDDDDDDDDB", "AAEEEEEEEEEEEAAAEEEEEEEEEEEAAAEEEEEEEEEEEAA", "AAEAAAAAAAAAEAAAEAAAAAAAAAEAAAEAAAAAAAAAEAA", "AAEAHHHIHHHAEAAAEAHHHIHHHAEAAAEAHHHIHHHAEAA", "AAFAAAAIAAAAFFFFFAAAAIAAAAFFFFFAAAAIAAAAEAA", "AAEAAAAIAAAAEAAAEAAAAIAAAAEAAAEAAAAIAAAAEAA", "AAFAAAAIAAAAFFFFFAAAAIAAAAFFFFFAAAAIAAAAEAA", "AAEAAAAIAAAAEAAAEAAAAIAAAAEAAAEAAAAIAAAAEAA", "AAEAAAAIAAAAEAAAEAAAAIAAAAEAAAEAAAAIAAAAEAA", "AAEAAAAIAAAAEAAAEAAAAIAAAAEAAAEAAAAIAAAAEAA", "AAGGGGGIGGGGGAAAGGGGGIGGGGGAAAGGGGGIGGGGGAA")
        .aisle("BDDDDDDDDDDDDDDDDDDDDDDDDDDDDDDDDDDDDDDDDDB", "AAEEEEEEEEEEEAAAEEEEEEEEEEEAAAEEEEEEEEEEEAA", "AAEAAAAAAAAAEAAAEAAAAAAAAAEAAAEAAAAAAAAAEAA", "AAEAAAAHAAAAEAAAEAAAAHAAAAEAAAEAAAAHAAAAEAA", "AAEAAAAAAAAAEAAAEAAAAAAAAAEAAAEAAAAAAAAAEAA", "AAEAAAAAAAAAEAAAEAAAAAAAAAEAAAEAAAAAAAAAEAA", "AAEAAAAAAAAAEAAAEAAAAAAAAAEAAAEAAAAAAAAAEAA", "AAEAAAAAAAAAEAAAEAAAAAAAAAEAAAEAAAAAAAAAEAA", "AAEAAAAAAAAAEAAAEAAAAAAAAAEAAAEAAAAAAAAAEAA", "AAEAAAAAAAAAEAAAEAAAAAAAAAEAAAEAAAAAAAAAEAA", "AAAAAAAGAAAAAAAAAAAAAGAAAAAAAAAAAAAGAAAAAAA")
        .aisle("BDDDDDDDDDDDDDDDDDDDDDDDDDDDDDDDDDDDDDDDDDB", "AAAEEEEEEEEEAAAAAEEEEEEEEEAAAAAEEEEEEEEEAAA", "AAAEAAAAAAAEAAAAAEAAAAAAAEAAAAAEAAAAAAAEAAA", "AAAEAAAHAAAEAAAAAEAAAHAAAEAAAAAEAAAHAAAEAAA", "AAAEAAAAAAAEAAAAAEAAAAAAAEAAAAAEAAAAAAAEAAA", "AAAEAAAAAAAEAAAAAEAAAAAAAEAAAAAEAAAAAAAEAAA", "AAAEAAAAAAAEAAAAAEAAAAAAAEAAAAAEAAAAAAAEAAA", "AAAEAAAAAAAEAAAAAEAAAAAAAEAAAAAEAAAAAAAEAAA", "AAAEAAAAAAAEAAAAAEAAAAAAAEAAAAAEAAAAAAAEAAA", "AAAEAAAAAAAEAAAAAEAAAAAAAEAAAAAEAAAAAAAEAAA", "AAAAAAAGAAAAAAAAAAAAAGAAAAAAAAAAAAAGAAAAAAA")
        .aisle("BDDDDDDDDDDDDDDDDDDDDDDDDDDDDDDDDDDDDDDDDDB", "AAAEEEEEEEEEAAAAAEEEEEEEEEAAAAAEEEEEEEEEAAA", "AAAEAAAAAAAEAAAAAEAAAAAAAEAAAAAEAAAAAAAEAAA", "AAAEAAAHAAAEAAAAAEAAAHAAAEAAAAAEAAAHAAAEAAA", "AAAEAAAAAAAEAAAAAEAAAAAAAEAAAAAEAAAAAAAEAAA", "AAAEAAAAAAAEAAAAAEAAAAAAAEAAAAAEAAAAAAAEAAA", "AAAEAAAAAAAEAAAAAEAAAAAAAEAAAAAEAAAAAAAEAAA", "AAAEAAAAAAAEAAAAAEAAAAAAAEAAAAAEAAAAAAAEAAA", "AAAEAAAAAAAEAAAAAEAAAAAAAEAAAAAEAAAAAAAEAAA", "AAAEAAAAAAAEAAAAAEAAAAAAAEAAAAAEAAAAAAAEAAA", "AAAAAAAGAAAAAAAAAAAAAGAAAAAAAAAAAAAGAAAAAAA")
        .aisle("BDDDDDDDDDDDDDDDDDDDDDDDDDDDDDDDDDDDDDDDDDB", "AAAAEEEEEEEAAAAAAAEEEEEEEAAAAAAAEEEEEEEAAAA", "AAAAEEAAAEEAAAAAAAEEAAAEEAAAAAAAEEAAAEEAAAA", "AAAAEEAAAEEAAAAAAAEEAAAEEAAAAAAAEEAAAEEAAAA", "AAAAEEAAAEEAAAAAAAEEAAAEEAAAAAAAEEAAAEEAAAA", "AAAAEEAAAEEAAAAAAAEEAAAEEAAAAAAAEEAAAEEAAAA", "AAAAEEAAAEEAAAAAAAEEAAAEEAAAAAAAEEAAAEEAAAA", "AAAAEEAAAEEAAAAAAAEEAAAEEAAAAAAAEEAAAEEAAAA", "AAAAEEAAAEEAAAAAAAEEAAAEEAAAAAAAEEAAAEEAAAA", "AAAAEEAAAEEAAAAAAAEEAAAEEAAAAAAAEEAAAEEAAAA", "AAAAAAAGAAAAAAAAAAAAAGAAAAAAAAAAAAAGAAAAAAA")
        .aisle("BDDDDDDDDDDDDDDDDDDDDDDDDDDDDDDDDDDDDDDDDDB", "AAAAAAEEEAAAAAAAAAAAEEEAAAAAAAAAAAEEEAAAAAA", "AAAAAAEEEAAAAAAAAAAAEEEAAAAAAAAAAAEEEAAAAAA", "AAAAAAEEEAAAAAAAAAAAEEEAAAAAAAAAAAEEEAAAAAA", "AAAAAAEEEAAAAAAAAAAAEEEAAAAAAAAAAAEEEAAAAAA", "AAAAAAEEEAAAAAAAAAAAEEEAAAAAAAAAAAEEEAAAAAA", "AAAAAAEEEAAAAAAAAAAAEEEAAAAAAAAAAAEEEAAAAAA", "AAAAAAEEEAAAAAAAAAAAEEEAAAAAAAAAAAEEEAAAAAA", "AAAAAAEEEAAAAAAAAAAAEEEAAAAAAAAAAAEEEAAAAAA", "AAAAAAEEEAAAAAAAAAAAEEEAAAAAAAAAAAEEEAAAAAA", "AAAAAAAGAAAAAAAAAAAAAGAAAAAAAAAAAAAGAAAAAAA")
        .aisle("BDDDDDDDDDDDDDDDDDDDDDDDDDDDDDDDDDDDDDDDDDB", "AAAAAAAAAAAAAAAAAAAAAAAAAAAAAAAAAAAAAAAAAAA", "AAAAAAAAAAAAAAAAAAAAAAAAAAAAAAAAAAAAAAAAAAA", "AAAAAAAAAAAAAAAAAAAAAAAAAAAAAAAAAAAAAAAAAAA", "AAAAAAAAAAAAAAAAAAAAAAAAAAAAAAAAAAAAAAAAAAA", "AAAAAAAAAAAAAAAAAAAAAAAAAAAAAAAAAAAAAAAAAAA", "AAAAAAAAAAAAAAAAAAAAAAAAAAAAAAAAAAAAAAAAAAA", "AAAAAAAAAAAAAAAAAAAAAAAAAAAAAAAAAAAAAAAAAAA", "AAAAAAAAAAAAAAAAAAAAAAAAAAAAAAAAAAAAAAAAAAA", "AAAAAAAAAAAAAAAAAAAAAAAAAAAAAAAAAAAAAAAAAAA", "AAAAAAAAAAAAAAAAAAAAAAAAAAAAAAAAAAAAAAAAAAA")
        .aisle("BBBBBBBBBBBBBBBBBBBBB@BBBBBBBBBBBBBBBBBBBBB", "AAAAAAAAAAAAAAAAAAAAAAAAAAAAAAAAAAAAAAAAAAA", "AAAAAAAAAAAAAAAAAAAAAAAAAAAAAAAAAAAAAAAAAAA", "AAAAAAAAAAAAAAAAAAAAAAAAAAAAAAAAAAAAAAAAAAA", "AAAAAAAAAAAAAAAAAAAAAAAAAAAAAAAAAAAAAAAAAAA", "AAAAAAAAAAAAAAAAAAAAAAAAAAAAAAAAAAAAAAAAAAA", "AAAAAAAAAAAAAAAAAAAAAAAAAAAAAAAAAAAAAAAAAAA", "AAAAAAAAAAAAAAAAAAAAAAAAAAAAAAAAAAAAAAAAAAA", "AAAAAAAAAAAAAAAAAAAAAAAAAAAAAAAAAAAAAAAAAAA", "AAAAAAAAAAAAAAAAAAAAAAAAAAAAAAAAAAAAAAAAAAA", "AAAAAAAAAAAAAAAAAAAAAAAAAAAAAAAAAAAAAAAAAAA")
           .where("A", Predicates.any())
           .where("E", Predicates.blocks("gtceu:solid_machine_casing"))
           .where("D", Predicates.blocks("gtceu:light_concrete"))
           .where("B", Predicates.blocks("gtceu:solid_machine_casing").setMinGlobalLimited(100)
                .or(Predicates.abilities(PartAbility.IMPORT_FLUIDS))
                .or(Predicates.abilities(PartAbility.IMPORT_ITEMS))
                .or(Predicates.abilities(PartAbility.EXPORT_ITEMS))
                .or(Predicates.abilities(PartAbility.EXPORT_FLUIDS))
                .or(Predicates.abilities(PartAbility.INPUT_ENERGY).setMaxGlobalLimited(2))
                .or(Predicates.abilities(PartAbility.MAINTENANCE).setExactLimit(1)))
           .where("F", Predicates.blocks("gtceu:tungstensteel_pipe_casing"))
           .where("G", Predicates.blocks("gtceu:hsla_steel_frame"))
           .where("H", Predicates.blocks("gtceu:steel_pipe_casing"))
           .where("I", Predicates.blocks("gtceu:steel_gearbox"))
           .where("@", Predicates.controller(Predicates.blocks(definition.get())))
            .build())
        .workableCasingModel('gtceu:block/casings/solid/machine_casing_solid_steel', 'gtceu:block/machines/chemical_reactor');
})





























